[2024-03-03T03:15:40.229+0000] {taskinstance.py:1979} INFO - Dependencies all met for dep_context=non-requeueable deps ti=<TaskInstance: fetch_data_files.get_files_1 scheduled__2016-01-31T00:00:00+00:00 [queued]>
[2024-03-03T03:15:40.241+0000] {taskinstance.py:1979} INFO - Dependencies all met for dep_context=requeueable deps ti=<TaskInstance: fetch_data_files.get_files_1 scheduled__2016-01-31T00:00:00+00:00 [queued]>
[2024-03-03T03:15:40.243+0000] {taskinstance.py:2193} INFO - Starting attempt 1 of 1
[2024-03-03T03:15:40.263+0000] {taskinstance.py:2214} INFO - Executing <Task(PythonOperator): get_files_1> on 2016-01-31 00:00:00+00:00
[2024-03-03T03:15:40.270+0000] {standard_task_runner.py:60} INFO - Started process 628 to run task
[2024-03-03T03:15:40.276+0000] {standard_task_runner.py:87} INFO - Running: ['***', 'tasks', 'run', 'fetch_data_files', 'get_files_1', 'scheduled__2016-01-31T00:00:00+00:00', '--job-id', '195', '--raw', '--subdir', 'DAGS_FOLDER/dummy_dag.py', '--cfg-path', '/tmp/tmp3rycl7ie']
[2024-03-03T03:15:40.280+0000] {standard_task_runner.py:88} INFO - Job 195: Subtask get_files_1
[2024-03-03T03:15:40.307+0000] {logging_mixin.py:188} WARNING - /home/***/.local/lib/python3.11/site-packages/***/settings.py:194 DeprecationWarning: The sql_alchemy_conn option in [core] has been moved to the sql_alchemy_conn option in [database] - the old setting has been used, but please update your config.
[2024-03-03T03:15:40.379+0000] {task_command.py:423} INFO - Running <TaskInstance: fetch_data_files.get_files_1 scheduled__2016-01-31T00:00:00+00:00 [running]> on host eb03c8b8b5fd
[2024-03-03T03:15:40.505+0000] {taskinstance.py:2510} INFO - Exporting env vars: AIRFLOW_CTX_DAG_OWNER='***' AIRFLOW_CTX_DAG_ID='fetch_data_files' AIRFLOW_CTX_TASK_ID='get_files_1' AIRFLOW_CTX_EXECUTION_DATE='2016-01-31T00:00:00+00:00' AIRFLOW_CTX_TRY_NUMBER='1' AIRFLOW_CTX_DAG_RUN_ID='scheduled__2016-01-31T00:00:00+00:00'
[2024-03-03T03:15:41.788+0000] {taskinstance.py:2728} ERROR - Task failed with exception
Traceback (most recent call last):
  File "/home/airflow/.local/lib/python3.11/site-packages/airflow/models/taskinstance.py", line 444, in _execute_task
    result = _execute_callable(context=context, **execute_callable_kwargs)
             ^^^^^^^^^^^^^^^^^^^^^^^^^^^^^^^^^^^^^^^^^^^^^^^^^^^^^^^^^^^^^
  File "/home/airflow/.local/lib/python3.11/site-packages/airflow/models/taskinstance.py", line 414, in _execute_callable
    return execute_callable(context=context, **execute_callable_kwargs)
           ^^^^^^^^^^^^^^^^^^^^^^^^^^^^^^^^^^^^^^^^^^^^^^^^^^^^^^^^^^^^
  File "/home/airflow/.local/lib/python3.11/site-packages/airflow/operators/python.py", line 200, in execute
    return_value = self.execute_callable()
                   ^^^^^^^^^^^^^^^^^^^^^^^
  File "/home/airflow/.local/lib/python3.11/site-packages/airflow/operators/python.py", line 217, in execute_callable
    return self.python_callable(*self.op_args, **self.op_kwargs)
           ^^^^^^^^^^^^^^^^^^^^^^^^^^^^^^^^^^^^^^^^^^^^^^^^^^^^^
  File "/opt/airflow/dags/dummy_dag.py", line 29, in download_years_list
    page = urlopen(url)
           ^^^^^^^^^^^^
  File "/usr/local/lib/python3.11/urllib/request.py", line 216, in urlopen
    return opener.open(url, data, timeout)
           ^^^^^^^^^^^^^^^^^^^^^^^^^^^^^^^
  File "/usr/local/lib/python3.11/urllib/request.py", line 525, in open
    response = meth(req, response)
               ^^^^^^^^^^^^^^^^^^^
  File "/usr/local/lib/python3.11/urllib/request.py", line 634, in http_response
    response = self.parent.error(
               ^^^^^^^^^^^^^^^^^^
  File "/usr/local/lib/python3.11/urllib/request.py", line 563, in error
    return self._call_chain(*args)
           ^^^^^^^^^^^^^^^^^^^^^^^
  File "/usr/local/lib/python3.11/urllib/request.py", line 496, in _call_chain
    result = func(*args)
             ^^^^^^^^^^^
  File "/usr/local/lib/python3.11/urllib/request.py", line 643, in http_error_default
    raise HTTPError(req.full_url, code, msg, hdrs, fp)
urllib.error.HTTPError: HTTP Error 404: Not Found
[2024-03-03T03:15:41.859+0000] {taskinstance.py:1149} INFO - Marking task as FAILED. dag_id=fetch_data_files, task_id=get_files_1, execution_date=20160131T000000, start_date=20240303T031540, end_date=20240303T031541
[2024-03-03T03:15:41.940+0000] {standard_task_runner.py:107} ERROR - Failed to execute job 195 for task get_files_1 (HTTP Error 404: Not Found; 628)
[2024-03-03T03:15:41.960+0000] {local_task_job_runner.py:234} INFO - Task exited with return code 1
[2024-03-03T03:15:42.016+0000] {taskinstance.py:3309} INFO - 0 downstream tasks scheduled from follow-on schedule check
[2024-03-03T03:30:17.747+0000] {taskinstance.py:1979} INFO - Dependencies all met for dep_context=non-requeueable deps ti=<TaskInstance: fetch_data_files.get_files_1 scheduled__2016-01-31T00:00:00+00:00 [queued]>
[2024-03-03T03:30:17.759+0000] {taskinstance.py:1979} INFO - Dependencies all met for dep_context=requeueable deps ti=<TaskInstance: fetch_data_files.get_files_1 scheduled__2016-01-31T00:00:00+00:00 [queued]>
[2024-03-03T03:30:17.760+0000] {taskinstance.py:2193} INFO - Starting attempt 1 of 1
[2024-03-03T03:30:17.778+0000] {taskinstance.py:2214} INFO - Executing <Task(PythonOperator): get_files_1> on 2016-01-31 00:00:00+00:00
[2024-03-03T03:30:17.785+0000] {standard_task_runner.py:60} INFO - Started process 655 to run task
[2024-03-03T03:30:17.788+0000] {standard_task_runner.py:87} INFO - Running: ['***', 'tasks', 'run', 'fetch_data_files', 'get_files_1', 'scheduled__2016-01-31T00:00:00+00:00', '--job-id', '191', '--raw', '--subdir', 'DAGS_FOLDER/dummy_dag.py', '--cfg-path', '/tmp/tmpbisu4pir']
[2024-03-03T03:30:17.792+0000] {standard_task_runner.py:88} INFO - Job 191: Subtask get_files_1
[2024-03-03T03:30:17.811+0000] {logging_mixin.py:188} WARNING - /home/***/.local/lib/python3.11/site-packages/***/settings.py:194 DeprecationWarning: The sql_alchemy_conn option in [core] has been moved to the sql_alchemy_conn option in [database] - the old setting has been used, but please update your config.
[2024-03-03T03:30:17.878+0000] {task_command.py:423} INFO - Running <TaskInstance: fetch_data_files.get_files_1 scheduled__2016-01-31T00:00:00+00:00 [running]> on host 716a53fa82e1
[2024-03-03T03:30:17.987+0000] {taskinstance.py:2510} INFO - Exporting env vars: AIRFLOW_CTX_DAG_OWNER='***' AIRFLOW_CTX_DAG_ID='fetch_data_files' AIRFLOW_CTX_TASK_ID='get_files_1' AIRFLOW_CTX_EXECUTION_DATE='2016-01-31T00:00:00+00:00' AIRFLOW_CTX_TRY_NUMBER='1' AIRFLOW_CTX_DAG_RUN_ID='scheduled__2016-01-31T00:00:00+00:00'
[2024-03-03T03:30:20.192+0000] {taskinstance.py:2728} ERROR - Task failed with exception
Traceback (most recent call last):
  File "/home/airflow/.local/lib/python3.11/site-packages/airflow/models/taskinstance.py", line 444, in _execute_task
    result = _execute_callable(context=context, **execute_callable_kwargs)
             ^^^^^^^^^^^^^^^^^^^^^^^^^^^^^^^^^^^^^^^^^^^^^^^^^^^^^^^^^^^^^
  File "/home/airflow/.local/lib/python3.11/site-packages/airflow/models/taskinstance.py", line 414, in _execute_callable
    return execute_callable(context=context, **execute_callable_kwargs)
           ^^^^^^^^^^^^^^^^^^^^^^^^^^^^^^^^^^^^^^^^^^^^^^^^^^^^^^^^^^^^
  File "/home/airflow/.local/lib/python3.11/site-packages/airflow/operators/python.py", line 200, in execute
    return_value = self.execute_callable()
                   ^^^^^^^^^^^^^^^^^^^^^^^
  File "/home/airflow/.local/lib/python3.11/site-packages/airflow/operators/python.py", line 217, in execute_callable
    return self.python_callable(*self.op_args, **self.op_kwargs)
           ^^^^^^^^^^^^^^^^^^^^^^^^^^^^^^^^^^^^^^^^^^^^^^^^^^^^^
  File "/opt/airflow/dags/dummy_dag.py", line 30, in download_years_list
    page = urlopen(url)
           ^^^^^^^^^^^^
  File "/usr/local/lib/python3.11/urllib/request.py", line 216, in urlopen
    return opener.open(url, data, timeout)
           ^^^^^^^^^^^^^^^^^^^^^^^^^^^^^^^
  File "/usr/local/lib/python3.11/urllib/request.py", line 525, in open
    response = meth(req, response)
               ^^^^^^^^^^^^^^^^^^^
  File "/usr/local/lib/python3.11/urllib/request.py", line 634, in http_response
    response = self.parent.error(
               ^^^^^^^^^^^^^^^^^^
  File "/usr/local/lib/python3.11/urllib/request.py", line 563, in error
    return self._call_chain(*args)
           ^^^^^^^^^^^^^^^^^^^^^^^
  File "/usr/local/lib/python3.11/urllib/request.py", line 496, in _call_chain
    result = func(*args)
             ^^^^^^^^^^^
  File "/usr/local/lib/python3.11/urllib/request.py", line 643, in http_error_default
    raise HTTPError(req.full_url, code, msg, hdrs, fp)
urllib.error.HTTPError: HTTP Error 404: Not Found
[2024-03-03T03:30:20.212+0000] {taskinstance.py:1149} INFO - Marking task as FAILED. dag_id=fetch_data_files, task_id=get_files_1, execution_date=20160131T000000, start_date=20240303T033017, end_date=20240303T033020
[2024-03-03T03:30:20.228+0000] {standard_task_runner.py:107} ERROR - Failed to execute job 191 for task get_files_1 (HTTP Error 404: Not Found; 655)
[2024-03-03T03:30:20.260+0000] {local_task_job_runner.py:234} INFO - Task exited with return code 1
[2024-03-03T03:30:20.288+0000] {taskinstance.py:3309} INFO - 0 downstream tasks scheduled from follow-on schedule check
