[2024-03-10T16:24:37.440+0000] {taskinstance.py:1979} INFO - Dependencies all met for dep_context=non-requeueable deps ti=<TaskInstance: processing.Create_images_6 manual__2024-03-10T16:24:12.612238+00:00 [queued]>
[2024-03-10T16:24:37.453+0000] {taskinstance.py:1979} INFO - Dependencies all met for dep_context=requeueable deps ti=<TaskInstance: processing.Create_images_6 manual__2024-03-10T16:24:12.612238+00:00 [queued]>
[2024-03-10T16:24:37.454+0000] {taskinstance.py:2193} INFO - Starting attempt 1 of 1
[2024-03-10T16:24:37.475+0000] {taskinstance.py:2214} INFO - Executing <Task(PythonOperator): Create_images_6> on 2024-03-10 16:24:12.612238+00:00
[2024-03-10T16:24:37.486+0000] {standard_task_runner.py:60} INFO - Started process 484 to run task
[2024-03-10T16:24:37.489+0000] {standard_task_runner.py:87} INFO - Running: ['***', 'tasks', 'run', 'processing', 'Create_images_6', 'manual__2024-03-10T16:24:12.612238+00:00', '--job-id', '25', '--raw', '--subdir', 'DAGS_FOLDER/process_data.py', '--cfg-path', '/tmp/tmpjxmj9xuh']
[2024-03-10T16:24:37.492+0000] {standard_task_runner.py:88} INFO - Job 25: Subtask Create_images_6
[2024-03-10T16:24:37.515+0000] {logging_mixin.py:188} WARNING - /home/***/.local/lib/python3.11/site-packages/***/settings.py:194 DeprecationWarning: The sql_alchemy_conn option in [core] has been moved to the sql_alchemy_conn option in [database] - the old setting has been used, but please update your config.
[2024-03-10T16:24:37.633+0000] {task_command.py:423} INFO - Running <TaskInstance: processing.Create_images_6 manual__2024-03-10T16:24:12.612238+00:00 [running]> on host 65d624ba7e11
[2024-03-10T16:24:37.810+0000] {taskinstance.py:2510} INFO - Exporting env vars: AIRFLOW_CTX_DAG_OWNER='***' AIRFLOW_CTX_DAG_ID='processing' AIRFLOW_CTX_TASK_ID='Create_images_6' AIRFLOW_CTX_EXECUTION_DATE='2024-03-10T16:24:12.612238+00:00' AIRFLOW_CTX_TRY_NUMBER='1' AIRFLOW_CTX_DAG_RUN_ID='manual__2024-03-10T16:24:12.612238+00:00'
[2024-03-10T16:24:37.874+0000] {taskinstance.py:2728} ERROR - Task failed with exception
Traceback (most recent call last):
  File "/home/airflow/.local/lib/python3.11/site-packages/airflow/models/taskinstance.py", line 444, in _execute_task
    result = _execute_callable(context=context, **execute_callable_kwargs)
             ^^^^^^^^^^^^^^^^^^^^^^^^^^^^^^^^^^^^^^^^^^^^^^^^^^^^^^^^^^^^^
  File "/home/airflow/.local/lib/python3.11/site-packages/airflow/models/taskinstance.py", line 414, in _execute_callable
    return execute_callable(context=context, **execute_callable_kwargs)
           ^^^^^^^^^^^^^^^^^^^^^^^^^^^^^^^^^^^^^^^^^^^^^^^^^^^^^^^^^^^^
  File "/home/airflow/.local/lib/python3.11/site-packages/airflow/operators/python.py", line 200, in execute
    return_value = self.execute_callable()
                   ^^^^^^^^^^^^^^^^^^^^^^^
  File "/home/airflow/.local/lib/python3.11/site-packages/airflow/operators/python.py", line 217, in execute_callable
    return self.python_callable(*self.op_args, **self.op_kwargs)
           ^^^^^^^^^^^^^^^^^^^^^^^^^^^^^^^^^^^^^^^^^^^^^^^^^^^^^
  File "/opt/airflow/dags/process_data.py", line 92, in map_maker
    df = df1.loc[df['DATE'] == num]
                 ^^
UnboundLocalError: cannot access local variable 'df' where it is not associated with a value
[2024-03-10T16:24:37.895+0000] {taskinstance.py:1149} INFO - Marking task as FAILED. dag_id=processing, task_id=Create_images_6, execution_date=20240310T162412, start_date=20240310T162437, end_date=20240310T162437
[2024-03-10T16:24:37.909+0000] {standard_task_runner.py:107} ERROR - Failed to execute job 25 for task Create_images_6 (cannot access local variable 'df' where it is not associated with a value; 484)
[2024-03-10T16:24:37.949+0000] {local_task_job_runner.py:234} INFO - Task exited with return code 1
[2024-03-10T16:24:37.975+0000] {taskinstance.py:3309} INFO - 0 downstream tasks scheduled from follow-on schedule check
