[2024-03-10T16:34:10.876+0000] {taskinstance.py:1979} INFO - Dependencies all met for dep_context=non-requeueable deps ti=<TaskInstance: processing.Create_images_3 manual__2024-03-10T16:33:45.985784+00:00 [queued]>
[2024-03-10T16:34:10.892+0000] {taskinstance.py:1979} INFO - Dependencies all met for dep_context=requeueable deps ti=<TaskInstance: processing.Create_images_3 manual__2024-03-10T16:33:45.985784+00:00 [queued]>
[2024-03-10T16:34:10.893+0000] {taskinstance.py:2193} INFO - Starting attempt 1 of 1
[2024-03-10T16:34:10.921+0000] {taskinstance.py:2214} INFO - Executing <Task(PythonOperator): Create_images_3> on 2024-03-10 16:33:45.985784+00:00
[2024-03-10T16:34:10.932+0000] {standard_task_runner.py:60} INFO - Started process 876 to run task
[2024-03-10T16:34:10.938+0000] {standard_task_runner.py:87} INFO - Running: ['***', 'tasks', 'run', 'processing', 'Create_images_3', 'manual__2024-03-10T16:33:45.985784+00:00', '--job-id', '61', '--raw', '--subdir', 'DAGS_FOLDER/process_data.py', '--cfg-path', '/tmp/tmp_m9k7xmq']
[2024-03-10T16:34:10.945+0000] {standard_task_runner.py:88} INFO - Job 61: Subtask Create_images_3
[2024-03-10T16:34:10.979+0000] {logging_mixin.py:188} WARNING - /home/***/.local/lib/python3.11/site-packages/***/settings.py:194 DeprecationWarning: The sql_alchemy_conn option in [core] has been moved to the sql_alchemy_conn option in [database] - the old setting has been used, but please update your config.
[2024-03-10T16:34:11.067+0000] {task_command.py:423} INFO - Running <TaskInstance: processing.Create_images_3 manual__2024-03-10T16:33:45.985784+00:00 [running]> on host 65d624ba7e11
[2024-03-10T16:34:11.203+0000] {taskinstance.py:2510} INFO - Exporting env vars: AIRFLOW_CTX_DAG_OWNER='***' AIRFLOW_CTX_DAG_ID='processing' AIRFLOW_CTX_TASK_ID='Create_images_3' AIRFLOW_CTX_EXECUTION_DATE='2024-03-10T16:33:45.985784+00:00' AIRFLOW_CTX_TRY_NUMBER='1' AIRFLOW_CTX_DAG_RUN_ID='manual__2024-03-10T16:33:45.985784+00:00'
[2024-03-10T16:34:11.596+0000] {taskinstance.py:2728} ERROR - Task failed with exception
Traceback (most recent call last):
  File "/home/airflow/.local/lib/python3.11/site-packages/airflow/models/taskinstance.py", line 444, in _execute_task
    result = _execute_callable(context=context, **execute_callable_kwargs)
             ^^^^^^^^^^^^^^^^^^^^^^^^^^^^^^^^^^^^^^^^^^^^^^^^^^^^^^^^^^^^^
  File "/home/airflow/.local/lib/python3.11/site-packages/airflow/models/taskinstance.py", line 414, in _execute_callable
    return execute_callable(context=context, **execute_callable_kwargs)
           ^^^^^^^^^^^^^^^^^^^^^^^^^^^^^^^^^^^^^^^^^^^^^^^^^^^^^^^^^^^^
  File "/home/airflow/.local/lib/python3.11/site-packages/airflow/operators/python.py", line 200, in execute
    return_value = self.execute_callable()
                   ^^^^^^^^^^^^^^^^^^^^^^^
  File "/home/airflow/.local/lib/python3.11/site-packages/airflow/operators/python.py", line 217, in execute_callable
    return self.python_callable(*self.op_args, **self.op_kwargs)
           ^^^^^^^^^^^^^^^^^^^^^^^^^^^^^^^^^^^^^^^^^^^^^^^^^^^^^
  File "/opt/airflow/dags/process_data.py", line 122, in map_maker
    gdf.plot(ax=ax, c = gdf[col], cmap = 'magma', vmin = round(min_val-0.1*val_range), vmax = round(max_val + 0.1*val_range))
                                                         ^^^^^^^^^^^^^^^^^^^^^^^^^^^^
ValueError: cannot convert float NaN to integer
[2024-03-10T16:34:11.619+0000] {taskinstance.py:1149} INFO - Marking task as FAILED. dag_id=processing, task_id=Create_images_3, execution_date=20240310T163345, start_date=20240310T163410, end_date=20240310T163411
[2024-03-10T16:34:11.648+0000] {standard_task_runner.py:107} ERROR - Failed to execute job 61 for task Create_images_3 (cannot convert float NaN to integer; 876)
[2024-03-10T16:34:11.673+0000] {local_task_job_runner.py:234} INFO - Task exited with return code 1
[2024-03-10T16:34:11.714+0000] {taskinstance.py:3309} INFO - 0 downstream tasks scheduled from follow-on schedule check
