[2024-03-03T02:50:34.404+0000] {taskinstance.py:1979} INFO - Dependencies all met for dep_context=non-requeueable deps ti=<TaskInstance: fetch_data_files.get_files scheduled__2019-03-02T00:00:00+00:00 [queued]>
[2024-03-03T02:50:34.417+0000] {taskinstance.py:1979} INFO - Dependencies all met for dep_context=requeueable deps ti=<TaskInstance: fetch_data_files.get_files scheduled__2019-03-02T00:00:00+00:00 [queued]>
[2024-03-03T02:50:34.419+0000] {taskinstance.py:2193} INFO - Starting attempt 1 of 1
[2024-03-03T02:50:34.440+0000] {taskinstance.py:2214} INFO - Executing <Task(PythonOperator): get_files> on 2019-03-02 00:00:00+00:00
[2024-03-03T02:50:34.448+0000] {standard_task_runner.py:60} INFO - Started process 2830 to run task
[2024-03-03T02:50:34.452+0000] {standard_task_runner.py:87} INFO - Running: ['***', 'tasks', 'run', 'fetch_data_files', 'get_files', 'scheduled__2019-03-02T00:00:00+00:00', '--job-id', '4152', '--raw', '--subdir', 'DAGS_FOLDER/dummy_dag.py', '--cfg-path', '/tmp/tmp3etdxxva']
[2024-03-03T02:50:34.456+0000] {standard_task_runner.py:88} INFO - Job 4152: Subtask get_files
[2024-03-03T02:50:34.479+0000] {logging_mixin.py:188} WARNING - /home/***/.local/lib/python3.11/site-packages/***/settings.py:194 DeprecationWarning: The sql_alchemy_conn option in [core] has been moved to the sql_alchemy_conn option in [database] - the old setting has been used, but please update your config.
[2024-03-03T02:50:34.537+0000] {task_command.py:423} INFO - Running <TaskInstance: fetch_data_files.get_files scheduled__2019-03-02T00:00:00+00:00 [running]> on host 887b52fd1a6d
[2024-03-03T02:50:34.653+0000] {taskinstance.py:2510} INFO - Exporting env vars: AIRFLOW_CTX_DAG_OWNER='***' AIRFLOW_CTX_DAG_ID='fetch_data_files' AIRFLOW_CTX_TASK_ID='get_files' AIRFLOW_CTX_EXECUTION_DATE='2019-03-02T00:00:00+00:00' AIRFLOW_CTX_TRY_NUMBER='1' AIRFLOW_CTX_DAG_RUN_ID='scheduled__2019-03-02T00:00:00+00:00'
[2024-03-03T02:50:36.941+0000] {taskinstance.py:2728} ERROR - Task failed with exception
Traceback (most recent call last):
  File "/home/airflow/.local/lib/python3.11/site-packages/airflow/models/taskinstance.py", line 444, in _execute_task
    result = _execute_callable(context=context, **execute_callable_kwargs)
             ^^^^^^^^^^^^^^^^^^^^^^^^^^^^^^^^^^^^^^^^^^^^^^^^^^^^^^^^^^^^^
  File "/home/airflow/.local/lib/python3.11/site-packages/airflow/models/taskinstance.py", line 414, in _execute_callable
    return execute_callable(context=context, **execute_callable_kwargs)
           ^^^^^^^^^^^^^^^^^^^^^^^^^^^^^^^^^^^^^^^^^^^^^^^^^^^^^^^^^^^^
  File "/home/airflow/.local/lib/python3.11/site-packages/airflow/operators/python.py", line 200, in execute
    return_value = self.execute_callable()
                   ^^^^^^^^^^^^^^^^^^^^^^^
  File "/home/airflow/.local/lib/python3.11/site-packages/airflow/operators/python.py", line 217, in execute_callable
    return self.python_callable(*self.op_args, **self.op_kwargs)
           ^^^^^^^^^^^^^^^^^^^^^^^^^^^^^^^^^^^^^^^^^^^^^^^^^^^^^
  File "/opt/airflow/dags/dummy_dag.py", line 40, in download_years_list
  File "/usr/local/lib/python3.11/urllib/request.py", line 251, in urlretrieve
    tfp = open(filename, 'wb')
          ^^^^^^^^^^^^^^^^^^^^
FileNotFoundError: [Errno 2] No such file or directory: '/opt/airflow/Files/Files/1901/02907099999.csv'
[2024-03-03T02:50:36.974+0000] {taskinstance.py:1149} INFO - Marking task as FAILED. dag_id=fetch_data_files, task_id=get_files, execution_date=20190302T000000, start_date=20240303T025034, end_date=20240303T025036
[2024-03-03T02:50:37.016+0000] {standard_task_runner.py:107} ERROR - Failed to execute job 4152 for task get_files ([Errno 2] No such file or directory: '/opt/airflow/Files/Files/1901/02907099999.csv'; 2830)
[2024-03-03T02:50:37.037+0000] {local_task_job_runner.py:234} INFO - Task exited with return code 1
[2024-03-03T02:50:37.062+0000] {taskinstance.py:3309} INFO - 0 downstream tasks scheduled from follow-on schedule check
