[2024-03-03T03:16:16.267+0000] {taskinstance.py:1979} INFO - Dependencies all met for dep_context=non-requeueable deps ti=<TaskInstance: fetch_data_files.get_files_6 scheduled__2016-02-25T00:00:00+00:00 [queued]>
[2024-03-03T03:16:16.284+0000] {taskinstance.py:1979} INFO - Dependencies all met for dep_context=requeueable deps ti=<TaskInstance: fetch_data_files.get_files_6 scheduled__2016-02-25T00:00:00+00:00 [queued]>
[2024-03-03T03:16:16.285+0000] {taskinstance.py:2193} INFO - Starting attempt 1 of 1
[2024-03-03T03:16:16.316+0000] {taskinstance.py:2214} INFO - Executing <Task(PythonOperator): get_files_6> on 2016-02-25 00:00:00+00:00
[2024-03-03T03:16:16.329+0000] {standard_task_runner.py:60} INFO - Started process 943 to run task
[2024-03-03T03:16:16.334+0000] {standard_task_runner.py:87} INFO - Running: ['***', 'tasks', 'run', 'fetch_data_files', 'get_files_6', 'scheduled__2016-02-25T00:00:00+00:00', '--job-id', '350', '--raw', '--subdir', 'DAGS_FOLDER/dummy_dag.py', '--cfg-path', '/tmp/tmpbb263nv9']
[2024-03-03T03:16:16.341+0000] {standard_task_runner.py:88} INFO - Job 350: Subtask get_files_6
[2024-03-03T03:16:16.374+0000] {logging_mixin.py:188} WARNING - /home/***/.local/lib/python3.11/site-packages/***/settings.py:194 DeprecationWarning: The sql_alchemy_conn option in [core] has been moved to the sql_alchemy_conn option in [database] - the old setting has been used, but please update your config.
[2024-03-03T03:16:16.461+0000] {task_command.py:423} INFO - Running <TaskInstance: fetch_data_files.get_files_6 scheduled__2016-02-25T00:00:00+00:00 [running]> on host eb03c8b8b5fd
[2024-03-03T03:16:16.618+0000] {taskinstance.py:2510} INFO - Exporting env vars: AIRFLOW_CTX_DAG_OWNER='***' AIRFLOW_CTX_DAG_ID='fetch_data_files' AIRFLOW_CTX_TASK_ID='get_files_6' AIRFLOW_CTX_EXECUTION_DATE='2016-02-25T00:00:00+00:00' AIRFLOW_CTX_TRY_NUMBER='1' AIRFLOW_CTX_DAG_RUN_ID='scheduled__2016-02-25T00:00:00+00:00'
[2024-03-03T03:16:17.921+0000] {taskinstance.py:2728} ERROR - Task failed with exception
Traceback (most recent call last):
  File "/home/airflow/.local/lib/python3.11/site-packages/airflow/models/taskinstance.py", line 444, in _execute_task
    result = _execute_callable(context=context, **execute_callable_kwargs)
             ^^^^^^^^^^^^^^^^^^^^^^^^^^^^^^^^^^^^^^^^^^^^^^^^^^^^^^^^^^^^^
  File "/home/airflow/.local/lib/python3.11/site-packages/airflow/models/taskinstance.py", line 414, in _execute_callable
    return execute_callable(context=context, **execute_callable_kwargs)
           ^^^^^^^^^^^^^^^^^^^^^^^^^^^^^^^^^^^^^^^^^^^^^^^^^^^^^^^^^^^^
  File "/home/airflow/.local/lib/python3.11/site-packages/airflow/operators/python.py", line 200, in execute
    return_value = self.execute_callable()
                   ^^^^^^^^^^^^^^^^^^^^^^^
  File "/home/airflow/.local/lib/python3.11/site-packages/airflow/operators/python.py", line 217, in execute_callable
    return self.python_callable(*self.op_args, **self.op_kwargs)
           ^^^^^^^^^^^^^^^^^^^^^^^^^^^^^^^^^^^^^^^^^^^^^^^^^^^^^
  File "/opt/airflow/dags/dummy_dag.py", line 29, in download_years_list
    page = urlopen(url)
           ^^^^^^^^^^^^
  File "/usr/local/lib/python3.11/urllib/request.py", line 216, in urlopen
    return opener.open(url, data, timeout)
           ^^^^^^^^^^^^^^^^^^^^^^^^^^^^^^^
  File "/usr/local/lib/python3.11/urllib/request.py", line 525, in open
    response = meth(req, response)
               ^^^^^^^^^^^^^^^^^^^
  File "/usr/local/lib/python3.11/urllib/request.py", line 634, in http_response
    response = self.parent.error(
               ^^^^^^^^^^^^^^^^^^
  File "/usr/local/lib/python3.11/urllib/request.py", line 563, in error
    return self._call_chain(*args)
           ^^^^^^^^^^^^^^^^^^^^^^^
  File "/usr/local/lib/python3.11/urllib/request.py", line 496, in _call_chain
    result = func(*args)
             ^^^^^^^^^^^
  File "/usr/local/lib/python3.11/urllib/request.py", line 643, in http_error_default
    raise HTTPError(req.full_url, code, msg, hdrs, fp)
urllib.error.HTTPError: HTTP Error 404: Not Found
[2024-03-03T03:16:17.966+0000] {taskinstance.py:1149} INFO - Marking task as FAILED. dag_id=fetch_data_files, task_id=get_files_6, execution_date=20160225T000000, start_date=20240303T031616, end_date=20240303T031617
[2024-03-03T03:16:18.044+0000] {standard_task_runner.py:107} ERROR - Failed to execute job 350 for task get_files_6 (HTTP Error 404: Not Found; 943)
[2024-03-03T03:16:18.084+0000] {local_task_job_runner.py:234} INFO - Task exited with return code 1
[2024-03-03T03:16:18.161+0000] {taskinstance.py:3309} INFO - 0 downstream tasks scheduled from follow-on schedule check
[2024-03-03T03:32:54.652+0000] {taskinstance.py:1979} INFO - Dependencies all met for dep_context=non-requeueable deps ti=<TaskInstance: fetch_data_files.get_files_6 scheduled__2016-02-25T00:00:00+00:00 [queued]>
[2024-03-03T03:32:54.665+0000] {taskinstance.py:1979} INFO - Dependencies all met for dep_context=requeueable deps ti=<TaskInstance: fetch_data_files.get_files_6 scheduled__2016-02-25T00:00:00+00:00 [queued]>
[2024-03-03T03:32:54.666+0000] {taskinstance.py:2193} INFO - Starting attempt 1 of 1
[2024-03-03T03:32:54.689+0000] {taskinstance.py:2214} INFO - Executing <Task(PythonOperator): get_files_6> on 2016-02-25 00:00:00+00:00
[2024-03-03T03:32:54.697+0000] {standard_task_runner.py:60} INFO - Started process 1006 to run task
[2024-03-03T03:32:54.705+0000] {standard_task_runner.py:87} INFO - Running: ['***', 'tasks', 'run', 'fetch_data_files', 'get_files_6', 'scheduled__2016-02-25T00:00:00+00:00', '--job-id', '345', '--raw', '--subdir', 'DAGS_FOLDER/dummy_dag.py', '--cfg-path', '/tmp/tmpbb2yeffd']
[2024-03-03T03:32:54.711+0000] {standard_task_runner.py:88} INFO - Job 345: Subtask get_files_6
[2024-03-03T03:32:54.738+0000] {logging_mixin.py:188} WARNING - /home/***/.local/lib/python3.11/site-packages/***/settings.py:194 DeprecationWarning: The sql_alchemy_conn option in [core] has been moved to the sql_alchemy_conn option in [database] - the old setting has been used, but please update your config.
[2024-03-03T03:32:54.812+0000] {task_command.py:423} INFO - Running <TaskInstance: fetch_data_files.get_files_6 scheduled__2016-02-25T00:00:00+00:00 [running]> on host 716a53fa82e1
[2024-03-03T03:32:54.961+0000] {taskinstance.py:2510} INFO - Exporting env vars: AIRFLOW_CTX_DAG_OWNER='***' AIRFLOW_CTX_DAG_ID='fetch_data_files' AIRFLOW_CTX_TASK_ID='get_files_6' AIRFLOW_CTX_EXECUTION_DATE='2016-02-25T00:00:00+00:00' AIRFLOW_CTX_TRY_NUMBER='1' AIRFLOW_CTX_DAG_RUN_ID='scheduled__2016-02-25T00:00:00+00:00'
[2024-03-03T03:32:57.895+0000] {python.py:202} INFO - Done. Returned value was: None
[2024-03-03T03:32:57.913+0000] {taskinstance.py:1149} INFO - Marking task as SUCCESS. dag_id=fetch_data_files, task_id=get_files_6, execution_date=20160225T000000, start_date=20240303T033254, end_date=20240303T033257
[2024-03-03T03:32:57.934+0000] {local_task_job_runner.py:234} INFO - Task exited with return code 0
[2024-03-03T03:32:57.954+0000] {taskinstance.py:3309} INFO - 0 downstream tasks scheduled from follow-on schedule check
