[2024-03-03T03:17:47.825+0000] {taskinstance.py:1979} INFO - Dependencies all met for dep_context=non-requeueable deps ti=<TaskInstance: fetch_data_files.get_files_3 scheduled__2016-03-25T00:00:00+00:00 [queued]>
[2024-03-03T03:17:47.845+0000] {taskinstance.py:1979} INFO - Dependencies all met for dep_context=requeueable deps ti=<TaskInstance: fetch_data_files.get_files_3 scheduled__2016-03-25T00:00:00+00:00 [queued]>
[2024-03-03T03:17:47.847+0000] {taskinstance.py:2193} INFO - Starting attempt 1 of 1
[2024-03-03T03:17:47.871+0000] {taskinstance.py:2214} INFO - Executing <Task(PythonOperator): get_files_3> on 2016-03-25 00:00:00+00:00
[2024-03-03T03:17:47.884+0000] {standard_task_runner.py:60} INFO - Started process 1306 to run task
[2024-03-03T03:17:47.890+0000] {standard_task_runner.py:87} INFO - Running: ['***', 'tasks', 'run', 'fetch_data_files', 'get_files_3', 'scheduled__2016-03-25T00:00:00+00:00', '--job-id', '522', '--raw', '--subdir', 'DAGS_FOLDER/dummy_dag.py', '--cfg-path', '/tmp/tmpsov77pit']
[2024-03-03T03:17:47.895+0000] {standard_task_runner.py:88} INFO - Job 522: Subtask get_files_3
[2024-03-03T03:17:47.927+0000] {logging_mixin.py:188} WARNING - /home/***/.local/lib/python3.11/site-packages/***/settings.py:194 DeprecationWarning: The sql_alchemy_conn option in [core] has been moved to the sql_alchemy_conn option in [database] - the old setting has been used, but please update your config.
[2024-03-03T03:17:48.031+0000] {task_command.py:423} INFO - Running <TaskInstance: fetch_data_files.get_files_3 scheduled__2016-03-25T00:00:00+00:00 [running]> on host eb03c8b8b5fd
[2024-03-03T03:17:48.180+0000] {taskinstance.py:2510} INFO - Exporting env vars: AIRFLOW_CTX_DAG_OWNER='***' AIRFLOW_CTX_DAG_ID='fetch_data_files' AIRFLOW_CTX_TASK_ID='get_files_3' AIRFLOW_CTX_EXECUTION_DATE='2016-03-25T00:00:00+00:00' AIRFLOW_CTX_TRY_NUMBER='1' AIRFLOW_CTX_DAG_RUN_ID='scheduled__2016-03-25T00:00:00+00:00'
[2024-03-03T03:17:49.281+0000] {taskinstance.py:2728} ERROR - Task failed with exception
Traceback (most recent call last):
  File "/home/airflow/.local/lib/python3.11/site-packages/airflow/models/taskinstance.py", line 444, in _execute_task
    result = _execute_callable(context=context, **execute_callable_kwargs)
             ^^^^^^^^^^^^^^^^^^^^^^^^^^^^^^^^^^^^^^^^^^^^^^^^^^^^^^^^^^^^^
  File "/home/airflow/.local/lib/python3.11/site-packages/airflow/models/taskinstance.py", line 414, in _execute_callable
    return execute_callable(context=context, **execute_callable_kwargs)
           ^^^^^^^^^^^^^^^^^^^^^^^^^^^^^^^^^^^^^^^^^^^^^^^^^^^^^^^^^^^^
  File "/home/airflow/.local/lib/python3.11/site-packages/airflow/operators/python.py", line 200, in execute
    return_value = self.execute_callable()
                   ^^^^^^^^^^^^^^^^^^^^^^^
  File "/home/airflow/.local/lib/python3.11/site-packages/airflow/operators/python.py", line 217, in execute_callable
    return self.python_callable(*self.op_args, **self.op_kwargs)
           ^^^^^^^^^^^^^^^^^^^^^^^^^^^^^^^^^^^^^^^^^^^^^^^^^^^^^
  File "/opt/airflow/dags/dummy_dag.py", line 29, in download_years_list
    page = urlopen(url)
           ^^^^^^^^^^^^
  File "/usr/local/lib/python3.11/urllib/request.py", line 216, in urlopen
    return opener.open(url, data, timeout)
           ^^^^^^^^^^^^^^^^^^^^^^^^^^^^^^^
  File "/usr/local/lib/python3.11/urllib/request.py", line 525, in open
    response = meth(req, response)
               ^^^^^^^^^^^^^^^^^^^
  File "/usr/local/lib/python3.11/urllib/request.py", line 634, in http_response
    response = self.parent.error(
               ^^^^^^^^^^^^^^^^^^
  File "/usr/local/lib/python3.11/urllib/request.py", line 563, in error
    return self._call_chain(*args)
           ^^^^^^^^^^^^^^^^^^^^^^^
  File "/usr/local/lib/python3.11/urllib/request.py", line 496, in _call_chain
    result = func(*args)
             ^^^^^^^^^^^
  File "/usr/local/lib/python3.11/urllib/request.py", line 643, in http_error_default
    raise HTTPError(req.full_url, code, msg, hdrs, fp)
urllib.error.HTTPError: HTTP Error 404: Not Found
[2024-03-03T03:17:49.302+0000] {taskinstance.py:1149} INFO - Marking task as FAILED. dag_id=fetch_data_files, task_id=get_files_3, execution_date=20160325T000000, start_date=20240303T031747, end_date=20240303T031749
[2024-03-03T03:17:49.325+0000] {standard_task_runner.py:107} ERROR - Failed to execute job 522 for task get_files_3 (HTTP Error 404: Not Found; 1306)
[2024-03-03T03:17:49.352+0000] {local_task_job_runner.py:234} INFO - Task exited with return code 1
[2024-03-03T03:17:49.385+0000] {taskinstance.py:3309} INFO - 0 downstream tasks scheduled from follow-on schedule check
[2024-03-03T03:35:13.809+0000] {taskinstance.py:1979} INFO - Dependencies all met for dep_context=non-requeueable deps ti=<TaskInstance: fetch_data_files.get_files_3 scheduled__2016-03-25T00:00:00+00:00 [queued]>
[2024-03-03T03:35:13.822+0000] {taskinstance.py:1979} INFO - Dependencies all met for dep_context=requeueable deps ti=<TaskInstance: fetch_data_files.get_files_3 scheduled__2016-03-25T00:00:00+00:00 [queued]>
[2024-03-03T03:35:13.823+0000] {taskinstance.py:2193} INFO - Starting attempt 1 of 1
[2024-03-03T03:35:13.845+0000] {taskinstance.py:2214} INFO - Executing <Task(PythonOperator): get_files_3> on 2016-03-25 00:00:00+00:00
[2024-03-03T03:35:13.855+0000] {standard_task_runner.py:60} INFO - Started process 1355 to run task
[2024-03-03T03:35:13.859+0000] {standard_task_runner.py:87} INFO - Running: ['***', 'tasks', 'run', 'fetch_data_files', 'get_files_3', 'scheduled__2016-03-25T00:00:00+00:00', '--job-id', '509', '--raw', '--subdir', 'DAGS_FOLDER/dummy_dag.py', '--cfg-path', '/tmp/tmp3q0wwmex']
[2024-03-03T03:35:13.864+0000] {standard_task_runner.py:88} INFO - Job 509: Subtask get_files_3
[2024-03-03T03:35:13.888+0000] {logging_mixin.py:188} WARNING - /home/***/.local/lib/python3.11/site-packages/***/settings.py:194 DeprecationWarning: The sql_alchemy_conn option in [core] has been moved to the sql_alchemy_conn option in [database] - the old setting has been used, but please update your config.
[2024-03-03T03:35:13.949+0000] {task_command.py:423} INFO - Running <TaskInstance: fetch_data_files.get_files_3 scheduled__2016-03-25T00:00:00+00:00 [running]> on host 716a53fa82e1
[2024-03-03T03:35:14.090+0000] {taskinstance.py:2510} INFO - Exporting env vars: AIRFLOW_CTX_DAG_OWNER='***' AIRFLOW_CTX_DAG_ID='fetch_data_files' AIRFLOW_CTX_TASK_ID='get_files_3' AIRFLOW_CTX_EXECUTION_DATE='2016-03-25T00:00:00+00:00' AIRFLOW_CTX_TRY_NUMBER='1' AIRFLOW_CTX_DAG_RUN_ID='scheduled__2016-03-25T00:00:00+00:00'
[2024-03-03T03:35:14.093+0000] {logging_mixin.py:188} INFO - [1943, 1944, 1945, 1946, 1947, 1948, 1949, 1950, 1951, 1952, 1953, 1954, 1955, 1956, 1957, 1958, 1959, 1960, 1961, 1962, 1963]
[2024-03-03T03:35:14.094+0000] {python.py:202} INFO - Done. Returned value was: None
[2024-03-03T03:35:14.108+0000] {taskinstance.py:1149} INFO - Marking task as SUCCESS. dag_id=fetch_data_files, task_id=get_files_3, execution_date=20160325T000000, start_date=20240303T033513, end_date=20240303T033514
[2024-03-03T03:35:14.154+0000] {local_task_job_runner.py:234} INFO - Task exited with return code 0
[2024-03-03T03:35:14.233+0000] {taskinstance.py:3309} INFO - 0 downstream tasks scheduled from follow-on schedule check
