[2024-03-03T03:11:47.644+0000] {taskinstance.py:1979} INFO - Dependencies all met for dep_context=non-requeueable deps ti=<TaskInstance: fetch_data_files.get_files_5 scheduled__2016-01-09T00:00:00+00:00 [queued]>
[2024-03-03T03:11:47.655+0000] {taskinstance.py:1979} INFO - Dependencies all met for dep_context=requeueable deps ti=<TaskInstance: fetch_data_files.get_files_5 scheduled__2016-01-09T00:00:00+00:00 [queued]>
[2024-03-03T03:11:47.655+0000] {taskinstance.py:2193} INFO - Starting attempt 1 of 1
[2024-03-03T03:11:47.673+0000] {taskinstance.py:2214} INFO - Executing <Task(PythonOperator): get_files_5> on 2016-01-09 00:00:00+00:00
[2024-03-03T03:11:47.682+0000] {standard_task_runner.py:60} INFO - Started process 296 to run task
[2024-03-03T03:11:47.686+0000] {standard_task_runner.py:87} INFO - Running: ['***', 'tasks', 'run', 'fetch_data_files', 'get_files_5', 'scheduled__2016-01-09T00:00:00+00:00', '--job-id', '52', '--raw', '--subdir', 'DAGS_FOLDER/dummy_dag.py', '--cfg-path', '/tmp/tmpgc_dawe2']
[2024-03-03T03:11:47.691+0000] {standard_task_runner.py:88} INFO - Job 52: Subtask get_files_5
[2024-03-03T03:11:47.714+0000] {logging_mixin.py:188} WARNING - /home/***/.local/lib/python3.11/site-packages/***/settings.py:194 DeprecationWarning: The sql_alchemy_conn option in [core] has been moved to the sql_alchemy_conn option in [database] - the old setting has been used, but please update your config.
[2024-03-03T03:11:47.773+0000] {task_command.py:423} INFO - Running <TaskInstance: fetch_data_files.get_files_5 scheduled__2016-01-09T00:00:00+00:00 [running]> on host eb03c8b8b5fd
[2024-03-03T03:11:47.875+0000] {taskinstance.py:2510} INFO - Exporting env vars: AIRFLOW_CTX_DAG_OWNER='***' AIRFLOW_CTX_DAG_ID='fetch_data_files' AIRFLOW_CTX_TASK_ID='get_files_5' AIRFLOW_CTX_EXECUTION_DATE='2016-01-09T00:00:00+00:00' AIRFLOW_CTX_TRY_NUMBER='1' AIRFLOW_CTX_DAG_RUN_ID='scheduled__2016-01-09T00:00:00+00:00'
[2024-03-03T03:11:49.214+0000] {taskinstance.py:2728} ERROR - Task failed with exception
Traceback (most recent call last):
  File "/home/airflow/.local/lib/python3.11/site-packages/airflow/models/taskinstance.py", line 444, in _execute_task
    result = _execute_callable(context=context, **execute_callable_kwargs)
             ^^^^^^^^^^^^^^^^^^^^^^^^^^^^^^^^^^^^^^^^^^^^^^^^^^^^^^^^^^^^^
  File "/home/airflow/.local/lib/python3.11/site-packages/airflow/models/taskinstance.py", line 414, in _execute_callable
    return execute_callable(context=context, **execute_callable_kwargs)
           ^^^^^^^^^^^^^^^^^^^^^^^^^^^^^^^^^^^^^^^^^^^^^^^^^^^^^^^^^^^^
  File "/home/airflow/.local/lib/python3.11/site-packages/airflow/operators/python.py", line 200, in execute
    return_value = self.execute_callable()
                   ^^^^^^^^^^^^^^^^^^^^^^^
  File "/home/airflow/.local/lib/python3.11/site-packages/airflow/operators/python.py", line 217, in execute_callable
    return self.python_callable(*self.op_args, **self.op_kwargs)
           ^^^^^^^^^^^^^^^^^^^^^^^^^^^^^^^^^^^^^^^^^^^^^^^^^^^^^
  File "/opt/airflow/dags/dummy_dag.py", line 29, in download_years_list
    page = urlopen(url)
           ^^^^^^^^^^^^
  File "/usr/local/lib/python3.11/urllib/request.py", line 216, in urlopen
    return opener.open(url, data, timeout)
           ^^^^^^^^^^^^^^^^^^^^^^^^^^^^^^^
  File "/usr/local/lib/python3.11/urllib/request.py", line 525, in open
    response = meth(req, response)
               ^^^^^^^^^^^^^^^^^^^
  File "/usr/local/lib/python3.11/urllib/request.py", line 634, in http_response
    response = self.parent.error(
               ^^^^^^^^^^^^^^^^^^
  File "/usr/local/lib/python3.11/urllib/request.py", line 563, in error
    return self._call_chain(*args)
           ^^^^^^^^^^^^^^^^^^^^^^^
  File "/usr/local/lib/python3.11/urllib/request.py", line 496, in _call_chain
    result = func(*args)
             ^^^^^^^^^^^
  File "/usr/local/lib/python3.11/urllib/request.py", line 643, in http_error_default
    raise HTTPError(req.full_url, code, msg, hdrs, fp)
urllib.error.HTTPError: HTTP Error 404: Not Found
[2024-03-03T03:11:49.252+0000] {taskinstance.py:1149} INFO - Marking task as FAILED. dag_id=fetch_data_files, task_id=get_files_5, execution_date=20160109T000000, start_date=20240303T031147, end_date=20240303T031149
[2024-03-03T03:11:49.309+0000] {standard_task_runner.py:107} ERROR - Failed to execute job 52 for task get_files_5 (HTTP Error 404: Not Found; 296)
[2024-03-03T03:11:49.363+0000] {local_task_job_runner.py:234} INFO - Task exited with return code 1
[2024-03-03T03:11:49.445+0000] {taskinstance.py:3309} INFO - 0 downstream tasks scheduled from follow-on schedule check
[2024-03-03T03:21:41.988+0000] {taskinstance.py:1979} INFO - Dependencies all met for dep_context=non-requeueable deps ti=<TaskInstance: fetch_data_files.get_files_5 scheduled__2016-01-09T00:00:00+00:00 [queued]>
[2024-03-03T03:21:42.006+0000] {taskinstance.py:1979} INFO - Dependencies all met for dep_context=requeueable deps ti=<TaskInstance: fetch_data_files.get_files_5 scheduled__2016-01-09T00:00:00+00:00 [queued]>
[2024-03-03T03:21:42.007+0000] {taskinstance.py:2193} INFO - Starting attempt 1 of 1
[2024-03-03T03:21:42.034+0000] {taskinstance.py:2214} INFO - Executing <Task(PythonOperator): get_files_5> on 2016-01-09 00:00:00+00:00
[2024-03-03T03:21:42.045+0000] {standard_task_runner.py:60} INFO - Started process 310 to run task
[2024-03-03T03:21:42.051+0000] {standard_task_runner.py:87} INFO - Running: ['***', 'tasks', 'run', 'fetch_data_files', 'get_files_5', 'scheduled__2016-01-09T00:00:00+00:00', '--job-id', '57', '--raw', '--subdir', 'DAGS_FOLDER/dummy_dag.py', '--cfg-path', '/tmp/tmppb9aq2tr']
[2024-03-03T03:21:42.057+0000] {standard_task_runner.py:88} INFO - Job 57: Subtask get_files_5
[2024-03-03T03:21:42.088+0000] {logging_mixin.py:188} WARNING - /home/***/.local/lib/python3.11/site-packages/***/settings.py:194 DeprecationWarning: The sql_alchemy_conn option in [core] has been moved to the sql_alchemy_conn option in [database] - the old setting has been used, but please update your config.
[2024-03-03T03:21:42.171+0000] {task_command.py:423} INFO - Running <TaskInstance: fetch_data_files.get_files_5 scheduled__2016-01-09T00:00:00+00:00 [running]> on host 716a53fa82e1
[2024-03-03T03:21:42.315+0000] {taskinstance.py:2510} INFO - Exporting env vars: AIRFLOW_CTX_DAG_OWNER='***' AIRFLOW_CTX_DAG_ID='fetch_data_files' AIRFLOW_CTX_TASK_ID='get_files_5' AIRFLOW_CTX_EXECUTION_DATE='2016-01-09T00:00:00+00:00' AIRFLOW_CTX_TRY_NUMBER='1' AIRFLOW_CTX_DAG_RUN_ID='scheduled__2016-01-09T00:00:00+00:00'
[2024-03-03T03:21:43.451+0000] {taskinstance.py:2728} ERROR - Task failed with exception
Traceback (most recent call last):
  File "/home/airflow/.local/lib/python3.11/site-packages/airflow/models/taskinstance.py", line 444, in _execute_task
    result = _execute_callable(context=context, **execute_callable_kwargs)
             ^^^^^^^^^^^^^^^^^^^^^^^^^^^^^^^^^^^^^^^^^^^^^^^^^^^^^^^^^^^^^
  File "/home/airflow/.local/lib/python3.11/site-packages/airflow/models/taskinstance.py", line 414, in _execute_callable
    return execute_callable(context=context, **execute_callable_kwargs)
           ^^^^^^^^^^^^^^^^^^^^^^^^^^^^^^^^^^^^^^^^^^^^^^^^^^^^^^^^^^^^
  File "/home/airflow/.local/lib/python3.11/site-packages/airflow/operators/python.py", line 200, in execute
    return_value = self.execute_callable()
                   ^^^^^^^^^^^^^^^^^^^^^^^
  File "/home/airflow/.local/lib/python3.11/site-packages/airflow/operators/python.py", line 217, in execute_callable
    return self.python_callable(*self.op_args, **self.op_kwargs)
           ^^^^^^^^^^^^^^^^^^^^^^^^^^^^^^^^^^^^^^^^^^^^^^^^^^^^^
  File "/opt/airflow/dags/dummy_dag.py", line 30, in download_years_list
    page = urlopen(url)
           ^^^^^^^^^^^^
  File "/usr/local/lib/python3.11/urllib/request.py", line 216, in urlopen
    return opener.open(url, data, timeout)
           ^^^^^^^^^^^^^^^^^^^^^^^^^^^^^^^
  File "/usr/local/lib/python3.11/urllib/request.py", line 525, in open
    response = meth(req, response)
               ^^^^^^^^^^^^^^^^^^^
  File "/usr/local/lib/python3.11/urllib/request.py", line 634, in http_response
    response = self.parent.error(
               ^^^^^^^^^^^^^^^^^^
  File "/usr/local/lib/python3.11/urllib/request.py", line 563, in error
    return self._call_chain(*args)
           ^^^^^^^^^^^^^^^^^^^^^^^
  File "/usr/local/lib/python3.11/urllib/request.py", line 496, in _call_chain
    result = func(*args)
             ^^^^^^^^^^^
  File "/usr/local/lib/python3.11/urllib/request.py", line 643, in http_error_default
    raise HTTPError(req.full_url, code, msg, hdrs, fp)
urllib.error.HTTPError: HTTP Error 404: Not Found
[2024-03-03T03:21:43.479+0000] {taskinstance.py:1149} INFO - Marking task as FAILED. dag_id=fetch_data_files, task_id=get_files_5, execution_date=20160109T000000, start_date=20240303T032141, end_date=20240303T032143
[2024-03-03T03:21:43.493+0000] {standard_task_runner.py:107} ERROR - Failed to execute job 57 for task get_files_5 (HTTP Error 404: Not Found; 310)
[2024-03-03T03:21:43.511+0000] {local_task_job_runner.py:234} INFO - Task exited with return code 1
[2024-03-03T03:21:43.545+0000] {taskinstance.py:3309} INFO - 0 downstream tasks scheduled from follow-on schedule check
