[2024-03-03T03:15:50.806+0000] {taskinstance.py:1979} INFO - Dependencies all met for dep_context=non-requeueable deps ti=<TaskInstance: fetch_data_files.get_files_3 scheduled__2016-02-07T00:00:00+00:00 [queued]>
[2024-03-03T03:15:50.819+0000] {taskinstance.py:1979} INFO - Dependencies all met for dep_context=requeueable deps ti=<TaskInstance: fetch_data_files.get_files_3 scheduled__2016-02-07T00:00:00+00:00 [queued]>
[2024-03-03T03:15:50.820+0000] {taskinstance.py:2193} INFO - Starting attempt 1 of 1
[2024-03-03T03:15:50.839+0000] {taskinstance.py:2214} INFO - Executing <Task(PythonOperator): get_files_3> on 2016-02-07 00:00:00+00:00
[2024-03-03T03:15:50.847+0000] {standard_task_runner.py:60} INFO - Started process 717 to run task
[2024-03-03T03:15:50.851+0000] {standard_task_runner.py:87} INFO - Running: ['***', 'tasks', 'run', 'fetch_data_files', 'get_files_3', 'scheduled__2016-02-07T00:00:00+00:00', '--job-id', '241', '--raw', '--subdir', 'DAGS_FOLDER/dummy_dag.py', '--cfg-path', '/tmp/tmp_f57cz4t']
[2024-03-03T03:15:50.854+0000] {standard_task_runner.py:88} INFO - Job 241: Subtask get_files_3
[2024-03-03T03:15:50.880+0000] {logging_mixin.py:188} WARNING - /home/***/.local/lib/python3.11/site-packages/***/settings.py:194 DeprecationWarning: The sql_alchemy_conn option in [core] has been moved to the sql_alchemy_conn option in [database] - the old setting has been used, but please update your config.
[2024-03-03T03:15:50.952+0000] {task_command.py:423} INFO - Running <TaskInstance: fetch_data_files.get_files_3 scheduled__2016-02-07T00:00:00+00:00 [running]> on host eb03c8b8b5fd
[2024-03-03T03:15:51.074+0000] {taskinstance.py:2510} INFO - Exporting env vars: AIRFLOW_CTX_DAG_OWNER='***' AIRFLOW_CTX_DAG_ID='fetch_data_files' AIRFLOW_CTX_TASK_ID='get_files_3' AIRFLOW_CTX_EXECUTION_DATE='2016-02-07T00:00:00+00:00' AIRFLOW_CTX_TRY_NUMBER='1' AIRFLOW_CTX_DAG_RUN_ID='scheduled__2016-02-07T00:00:00+00:00'
[2024-03-03T03:15:52.222+0000] {taskinstance.py:2728} ERROR - Task failed with exception
Traceback (most recent call last):
  File "/home/airflow/.local/lib/python3.11/site-packages/airflow/models/taskinstance.py", line 444, in _execute_task
    result = _execute_callable(context=context, **execute_callable_kwargs)
             ^^^^^^^^^^^^^^^^^^^^^^^^^^^^^^^^^^^^^^^^^^^^^^^^^^^^^^^^^^^^^
  File "/home/airflow/.local/lib/python3.11/site-packages/airflow/models/taskinstance.py", line 414, in _execute_callable
    return execute_callable(context=context, **execute_callable_kwargs)
           ^^^^^^^^^^^^^^^^^^^^^^^^^^^^^^^^^^^^^^^^^^^^^^^^^^^^^^^^^^^^
  File "/home/airflow/.local/lib/python3.11/site-packages/airflow/operators/python.py", line 200, in execute
    return_value = self.execute_callable()
                   ^^^^^^^^^^^^^^^^^^^^^^^
  File "/home/airflow/.local/lib/python3.11/site-packages/airflow/operators/python.py", line 217, in execute_callable
    return self.python_callable(*self.op_args, **self.op_kwargs)
           ^^^^^^^^^^^^^^^^^^^^^^^^^^^^^^^^^^^^^^^^^^^^^^^^^^^^^
  File "/opt/airflow/dags/dummy_dag.py", line 29, in download_years_list
    page = urlopen(url)
           ^^^^^^^^^^^^
  File "/usr/local/lib/python3.11/urllib/request.py", line 216, in urlopen
    return opener.open(url, data, timeout)
           ^^^^^^^^^^^^^^^^^^^^^^^^^^^^^^^
  File "/usr/local/lib/python3.11/urllib/request.py", line 525, in open
    response = meth(req, response)
               ^^^^^^^^^^^^^^^^^^^
  File "/usr/local/lib/python3.11/urllib/request.py", line 634, in http_response
    response = self.parent.error(
               ^^^^^^^^^^^^^^^^^^
  File "/usr/local/lib/python3.11/urllib/request.py", line 563, in error
    return self._call_chain(*args)
           ^^^^^^^^^^^^^^^^^^^^^^^
  File "/usr/local/lib/python3.11/urllib/request.py", line 496, in _call_chain
    result = func(*args)
             ^^^^^^^^^^^
  File "/usr/local/lib/python3.11/urllib/request.py", line 643, in http_error_default
    raise HTTPError(req.full_url, code, msg, hdrs, fp)
urllib.error.HTTPError: HTTP Error 404: Not Found
[2024-03-03T03:15:52.277+0000] {taskinstance.py:1149} INFO - Marking task as FAILED. dag_id=fetch_data_files, task_id=get_files_3, execution_date=20160207T000000, start_date=20240303T031550, end_date=20240303T031552
[2024-03-03T03:15:52.320+0000] {standard_task_runner.py:107} ERROR - Failed to execute job 241 for task get_files_3 (HTTP Error 404: Not Found; 717)
[2024-03-03T03:15:52.356+0000] {local_task_job_runner.py:234} INFO - Task exited with return code 1
[2024-03-03T03:15:52.387+0000] {taskinstance.py:3309} INFO - 0 downstream tasks scheduled from follow-on schedule check
[2024-03-03T03:31:46.296+0000] {taskinstance.py:1979} INFO - Dependencies all met for dep_context=non-requeueable deps ti=<TaskInstance: fetch_data_files.get_files_3 scheduled__2016-02-07T00:00:00+00:00 [queued]>
[2024-03-03T03:31:46.313+0000] {taskinstance.py:1979} INFO - Dependencies all met for dep_context=requeueable deps ti=<TaskInstance: fetch_data_files.get_files_3 scheduled__2016-02-07T00:00:00+00:00 [queued]>
[2024-03-03T03:31:46.314+0000] {taskinstance.py:2193} INFO - Starting attempt 1 of 1
[2024-03-03T03:31:46.340+0000] {taskinstance.py:2214} INFO - Executing <Task(PythonOperator): get_files_3> on 2016-02-07 00:00:00+00:00
[2024-03-03T03:31:46.348+0000] {standard_task_runner.py:60} INFO - Started process 755 to run task
[2024-03-03T03:31:46.354+0000] {standard_task_runner.py:87} INFO - Running: ['***', 'tasks', 'run', 'fetch_data_files', 'get_files_3', 'scheduled__2016-02-07T00:00:00+00:00', '--job-id', '227', '--raw', '--subdir', 'DAGS_FOLDER/dummy_dag.py', '--cfg-path', '/tmp/tmph247su69']
[2024-03-03T03:31:46.358+0000] {standard_task_runner.py:88} INFO - Job 227: Subtask get_files_3
[2024-03-03T03:31:46.382+0000] {logging_mixin.py:188} WARNING - /home/***/.local/lib/python3.11/site-packages/***/settings.py:194 DeprecationWarning: The sql_alchemy_conn option in [core] has been moved to the sql_alchemy_conn option in [database] - the old setting has been used, but please update your config.
[2024-03-03T03:31:46.451+0000] {task_command.py:423} INFO - Running <TaskInstance: fetch_data_files.get_files_3 scheduled__2016-02-07T00:00:00+00:00 [running]> on host 716a53fa82e1
[2024-03-03T03:31:46.629+0000] {taskinstance.py:2510} INFO - Exporting env vars: AIRFLOW_CTX_DAG_OWNER='***' AIRFLOW_CTX_DAG_ID='fetch_data_files' AIRFLOW_CTX_TASK_ID='get_files_3' AIRFLOW_CTX_EXECUTION_DATE='2016-02-07T00:00:00+00:00' AIRFLOW_CTX_TRY_NUMBER='1' AIRFLOW_CTX_DAG_RUN_ID='scheduled__2016-02-07T00:00:00+00:00'
[2024-03-03T03:31:47.845+0000] {taskinstance.py:2728} ERROR - Task failed with exception
Traceback (most recent call last):
  File "/home/airflow/.local/lib/python3.11/site-packages/airflow/models/taskinstance.py", line 444, in _execute_task
    result = _execute_callable(context=context, **execute_callable_kwargs)
             ^^^^^^^^^^^^^^^^^^^^^^^^^^^^^^^^^^^^^^^^^^^^^^^^^^^^^^^^^^^^^
  File "/home/airflow/.local/lib/python3.11/site-packages/airflow/models/taskinstance.py", line 414, in _execute_callable
    return execute_callable(context=context, **execute_callable_kwargs)
           ^^^^^^^^^^^^^^^^^^^^^^^^^^^^^^^^^^^^^^^^^^^^^^^^^^^^^^^^^^^^
  File "/home/airflow/.local/lib/python3.11/site-packages/airflow/operators/python.py", line 200, in execute
    return_value = self.execute_callable()
                   ^^^^^^^^^^^^^^^^^^^^^^^
  File "/home/airflow/.local/lib/python3.11/site-packages/airflow/operators/python.py", line 217, in execute_callable
    return self.python_callable(*self.op_args, **self.op_kwargs)
           ^^^^^^^^^^^^^^^^^^^^^^^^^^^^^^^^^^^^^^^^^^^^^^^^^^^^^
  File "/opt/airflow/dags/dummy_dag.py", line 30, in download_years_list
    page = urlopen(url)
           ^^^^^^^^^^^^
  File "/usr/local/lib/python3.11/urllib/request.py", line 216, in urlopen
    return opener.open(url, data, timeout)
           ^^^^^^^^^^^^^^^^^^^^^^^^^^^^^^^
  File "/usr/local/lib/python3.11/urllib/request.py", line 525, in open
    response = meth(req, response)
               ^^^^^^^^^^^^^^^^^^^
  File "/usr/local/lib/python3.11/urllib/request.py", line 634, in http_response
    response = self.parent.error(
               ^^^^^^^^^^^^^^^^^^
  File "/usr/local/lib/python3.11/urllib/request.py", line 563, in error
    return self._call_chain(*args)
           ^^^^^^^^^^^^^^^^^^^^^^^
  File "/usr/local/lib/python3.11/urllib/request.py", line 496, in _call_chain
    result = func(*args)
             ^^^^^^^^^^^
  File "/usr/local/lib/python3.11/urllib/request.py", line 643, in http_error_default
    raise HTTPError(req.full_url, code, msg, hdrs, fp)
urllib.error.HTTPError: HTTP Error 404: Not Found
[2024-03-03T03:31:47.890+0000] {taskinstance.py:1149} INFO - Marking task as FAILED. dag_id=fetch_data_files, task_id=get_files_3, execution_date=20160207T000000, start_date=20240303T033146, end_date=20240303T033147
[2024-03-03T03:31:47.938+0000] {standard_task_runner.py:107} ERROR - Failed to execute job 227 for task get_files_3 (HTTP Error 404: Not Found; 755)
[2024-03-03T03:31:47.976+0000] {local_task_job_runner.py:234} INFO - Task exited with return code 1
[2024-03-03T03:31:48.013+0000] {taskinstance.py:3309} INFO - 0 downstream tasks scheduled from follow-on schedule check
