[2024-03-03T03:11:47.643+0000] {taskinstance.py:1979} INFO - Dependencies all met for dep_context=non-requeueable deps ti=<TaskInstance: fetch_data_files.get_files_4 scheduled__2016-01-09T00:00:00+00:00 [queued]>
[2024-03-03T03:11:47.654+0000] {taskinstance.py:1979} INFO - Dependencies all met for dep_context=requeueable deps ti=<TaskInstance: fetch_data_files.get_files_4 scheduled__2016-01-09T00:00:00+00:00 [queued]>
[2024-03-03T03:11:47.654+0000] {taskinstance.py:2193} INFO - Starting attempt 1 of 1
[2024-03-03T03:11:47.672+0000] {taskinstance.py:2214} INFO - Executing <Task(PythonOperator): get_files_4> on 2016-01-09 00:00:00+00:00
[2024-03-03T03:11:47.683+0000] {standard_task_runner.py:60} INFO - Started process 294 to run task
[2024-03-03T03:11:47.690+0000] {standard_task_runner.py:87} INFO - Running: ['***', 'tasks', 'run', 'fetch_data_files', 'get_files_4', 'scheduled__2016-01-09T00:00:00+00:00', '--job-id', '54', '--raw', '--subdir', 'DAGS_FOLDER/dummy_dag.py', '--cfg-path', '/tmp/tmpyxlr882x']
[2024-03-03T03:11:47.694+0000] {standard_task_runner.py:88} INFO - Job 54: Subtask get_files_4
[2024-03-03T03:11:47.717+0000] {logging_mixin.py:188} WARNING - /home/***/.local/lib/python3.11/site-packages/***/settings.py:194 DeprecationWarning: The sql_alchemy_conn option in [core] has been moved to the sql_alchemy_conn option in [database] - the old setting has been used, but please update your config.
[2024-03-03T03:11:47.776+0000] {task_command.py:423} INFO - Running <TaskInstance: fetch_data_files.get_files_4 scheduled__2016-01-09T00:00:00+00:00 [running]> on host eb03c8b8b5fd
[2024-03-03T03:11:47.885+0000] {taskinstance.py:2510} INFO - Exporting env vars: AIRFLOW_CTX_DAG_OWNER='***' AIRFLOW_CTX_DAG_ID='fetch_data_files' AIRFLOW_CTX_TASK_ID='get_files_4' AIRFLOW_CTX_EXECUTION_DATE='2016-01-09T00:00:00+00:00' AIRFLOW_CTX_TRY_NUMBER='1' AIRFLOW_CTX_DAG_RUN_ID='scheduled__2016-01-09T00:00:00+00:00'
[2024-03-03T03:11:49.210+0000] {taskinstance.py:2728} ERROR - Task failed with exception
Traceback (most recent call last):
  File "/home/airflow/.local/lib/python3.11/site-packages/airflow/models/taskinstance.py", line 444, in _execute_task
    result = _execute_callable(context=context, **execute_callable_kwargs)
             ^^^^^^^^^^^^^^^^^^^^^^^^^^^^^^^^^^^^^^^^^^^^^^^^^^^^^^^^^^^^^
  File "/home/airflow/.local/lib/python3.11/site-packages/airflow/models/taskinstance.py", line 414, in _execute_callable
    return execute_callable(context=context, **execute_callable_kwargs)
           ^^^^^^^^^^^^^^^^^^^^^^^^^^^^^^^^^^^^^^^^^^^^^^^^^^^^^^^^^^^^
  File "/home/airflow/.local/lib/python3.11/site-packages/airflow/operators/python.py", line 200, in execute
    return_value = self.execute_callable()
                   ^^^^^^^^^^^^^^^^^^^^^^^
  File "/home/airflow/.local/lib/python3.11/site-packages/airflow/operators/python.py", line 217, in execute_callable
    return self.python_callable(*self.op_args, **self.op_kwargs)
           ^^^^^^^^^^^^^^^^^^^^^^^^^^^^^^^^^^^^^^^^^^^^^^^^^^^^^
  File "/opt/airflow/dags/dummy_dag.py", line 29, in download_years_list
    page = urlopen(url)
           ^^^^^^^^^^^^
  File "/usr/local/lib/python3.11/urllib/request.py", line 216, in urlopen
    return opener.open(url, data, timeout)
           ^^^^^^^^^^^^^^^^^^^^^^^^^^^^^^^
  File "/usr/local/lib/python3.11/urllib/request.py", line 525, in open
    response = meth(req, response)
               ^^^^^^^^^^^^^^^^^^^
  File "/usr/local/lib/python3.11/urllib/request.py", line 634, in http_response
    response = self.parent.error(
               ^^^^^^^^^^^^^^^^^^
  File "/usr/local/lib/python3.11/urllib/request.py", line 563, in error
    return self._call_chain(*args)
           ^^^^^^^^^^^^^^^^^^^^^^^
  File "/usr/local/lib/python3.11/urllib/request.py", line 496, in _call_chain
    result = func(*args)
             ^^^^^^^^^^^
  File "/usr/local/lib/python3.11/urllib/request.py", line 643, in http_error_default
    raise HTTPError(req.full_url, code, msg, hdrs, fp)
urllib.error.HTTPError: HTTP Error 404: Not Found
[2024-03-03T03:11:49.244+0000] {taskinstance.py:1149} INFO - Marking task as FAILED. dag_id=fetch_data_files, task_id=get_files_4, execution_date=20160109T000000, start_date=20240303T031147, end_date=20240303T031149
[2024-03-03T03:11:49.267+0000] {standard_task_runner.py:107} ERROR - Failed to execute job 54 for task get_files_4 (HTTP Error 404: Not Found; 294)
[2024-03-03T03:11:49.311+0000] {local_task_job_runner.py:234} INFO - Task exited with return code 1
[2024-03-03T03:11:49.360+0000] {taskinstance.py:3309} INFO - 0 downstream tasks scheduled from follow-on schedule check
[2024-03-03T03:21:42.016+0000] {taskinstance.py:1979} INFO - Dependencies all met for dep_context=non-requeueable deps ti=<TaskInstance: fetch_data_files.get_files_4 scheduled__2016-01-09T00:00:00+00:00 [queued]>
[2024-03-03T03:21:42.036+0000] {taskinstance.py:1979} INFO - Dependencies all met for dep_context=requeueable deps ti=<TaskInstance: fetch_data_files.get_files_4 scheduled__2016-01-09T00:00:00+00:00 [queued]>
[2024-03-03T03:21:42.037+0000] {taskinstance.py:2193} INFO - Starting attempt 1 of 1
[2024-03-03T03:21:42.061+0000] {taskinstance.py:2214} INFO - Executing <Task(PythonOperator): get_files_4> on 2016-01-09 00:00:00+00:00
[2024-03-03T03:21:42.072+0000] {standard_task_runner.py:60} INFO - Started process 313 to run task
[2024-03-03T03:21:42.078+0000] {standard_task_runner.py:87} INFO - Running: ['***', 'tasks', 'run', 'fetch_data_files', 'get_files_4', 'scheduled__2016-01-09T00:00:00+00:00', '--job-id', '60', '--raw', '--subdir', 'DAGS_FOLDER/dummy_dag.py', '--cfg-path', '/tmp/tmp_yh4r3v6']
[2024-03-03T03:21:42.082+0000] {standard_task_runner.py:88} INFO - Job 60: Subtask get_files_4
[2024-03-03T03:21:42.113+0000] {logging_mixin.py:188} WARNING - /home/***/.local/lib/python3.11/site-packages/***/settings.py:194 DeprecationWarning: The sql_alchemy_conn option in [core] has been moved to the sql_alchemy_conn option in [database] - the old setting has been used, but please update your config.
[2024-03-03T03:21:42.187+0000] {task_command.py:423} INFO - Running <TaskInstance: fetch_data_files.get_files_4 scheduled__2016-01-09T00:00:00+00:00 [running]> on host 716a53fa82e1
[2024-03-03T03:21:42.329+0000] {taskinstance.py:2510} INFO - Exporting env vars: AIRFLOW_CTX_DAG_OWNER='***' AIRFLOW_CTX_DAG_ID='fetch_data_files' AIRFLOW_CTX_TASK_ID='get_files_4' AIRFLOW_CTX_EXECUTION_DATE='2016-01-09T00:00:00+00:00' AIRFLOW_CTX_TRY_NUMBER='1' AIRFLOW_CTX_DAG_RUN_ID='scheduled__2016-01-09T00:00:00+00:00'
[2024-03-03T03:21:43.471+0000] {taskinstance.py:2728} ERROR - Task failed with exception
Traceback (most recent call last):
  File "/home/airflow/.local/lib/python3.11/site-packages/airflow/models/taskinstance.py", line 444, in _execute_task
    result = _execute_callable(context=context, **execute_callable_kwargs)
             ^^^^^^^^^^^^^^^^^^^^^^^^^^^^^^^^^^^^^^^^^^^^^^^^^^^^^^^^^^^^^
  File "/home/airflow/.local/lib/python3.11/site-packages/airflow/models/taskinstance.py", line 414, in _execute_callable
    return execute_callable(context=context, **execute_callable_kwargs)
           ^^^^^^^^^^^^^^^^^^^^^^^^^^^^^^^^^^^^^^^^^^^^^^^^^^^^^^^^^^^^
  File "/home/airflow/.local/lib/python3.11/site-packages/airflow/operators/python.py", line 200, in execute
    return_value = self.execute_callable()
                   ^^^^^^^^^^^^^^^^^^^^^^^
  File "/home/airflow/.local/lib/python3.11/site-packages/airflow/operators/python.py", line 217, in execute_callable
    return self.python_callable(*self.op_args, **self.op_kwargs)
           ^^^^^^^^^^^^^^^^^^^^^^^^^^^^^^^^^^^^^^^^^^^^^^^^^^^^^
  File "/opt/airflow/dags/dummy_dag.py", line 30, in download_years_list
    page = urlopen(url)
           ^^^^^^^^^^^^
  File "/usr/local/lib/python3.11/urllib/request.py", line 216, in urlopen
    return opener.open(url, data, timeout)
           ^^^^^^^^^^^^^^^^^^^^^^^^^^^^^^^
  File "/usr/local/lib/python3.11/urllib/request.py", line 525, in open
    response = meth(req, response)
               ^^^^^^^^^^^^^^^^^^^
  File "/usr/local/lib/python3.11/urllib/request.py", line 634, in http_response
    response = self.parent.error(
               ^^^^^^^^^^^^^^^^^^
  File "/usr/local/lib/python3.11/urllib/request.py", line 563, in error
    return self._call_chain(*args)
           ^^^^^^^^^^^^^^^^^^^^^^^
  File "/usr/local/lib/python3.11/urllib/request.py", line 496, in _call_chain
    result = func(*args)
             ^^^^^^^^^^^
  File "/usr/local/lib/python3.11/urllib/request.py", line 643, in http_error_default
    raise HTTPError(req.full_url, code, msg, hdrs, fp)
urllib.error.HTTPError: HTTP Error 404: Not Found
[2024-03-03T03:21:43.495+0000] {taskinstance.py:1149} INFO - Marking task as FAILED. dag_id=fetch_data_files, task_id=get_files_4, execution_date=20160109T000000, start_date=20240303T032142, end_date=20240303T032143
[2024-03-03T03:21:43.509+0000] {standard_task_runner.py:107} ERROR - Failed to execute job 60 for task get_files_4 (HTTP Error 404: Not Found; 313)
[2024-03-03T03:21:43.539+0000] {local_task_job_runner.py:234} INFO - Task exited with return code 1
[2024-03-03T03:21:43.576+0000] {taskinstance.py:3309} INFO - 0 downstream tasks scheduled from follow-on schedule check
