[2024-03-03T03:15:36.620+0000] {taskinstance.py:1979} INFO - Dependencies all met for dep_context=non-requeueable deps ti=<TaskInstance: fetch_data_files.get_files_3 scheduled__2016-01-29T00:00:00+00:00 [queued]>
[2024-03-03T03:15:36.636+0000] {taskinstance.py:1979} INFO - Dependencies all met for dep_context=requeueable deps ti=<TaskInstance: fetch_data_files.get_files_3 scheduled__2016-01-29T00:00:00+00:00 [queued]>
[2024-03-03T03:15:36.637+0000] {taskinstance.py:2193} INFO - Starting attempt 1 of 1
[2024-03-03T03:15:36.663+0000] {taskinstance.py:2214} INFO - Executing <Task(PythonOperator): get_files_3> on 2016-01-29 00:00:00+00:00
[2024-03-03T03:15:36.673+0000] {standard_task_runner.py:60} INFO - Started process 608 to run task
[2024-03-03T03:15:36.679+0000] {standard_task_runner.py:87} INFO - Running: ['***', 'tasks', 'run', 'fetch_data_files', 'get_files_3', 'scheduled__2016-01-29T00:00:00+00:00', '--job-id', '185', '--raw', '--subdir', 'DAGS_FOLDER/dummy_dag.py', '--cfg-path', '/tmp/tmprq6g8gld']
[2024-03-03T03:15:36.683+0000] {standard_task_runner.py:88} INFO - Job 185: Subtask get_files_3
[2024-03-03T03:15:36.716+0000] {logging_mixin.py:188} WARNING - /home/***/.local/lib/python3.11/site-packages/***/settings.py:194 DeprecationWarning: The sql_alchemy_conn option in [core] has been moved to the sql_alchemy_conn option in [database] - the old setting has been used, but please update your config.
[2024-03-03T03:15:36.790+0000] {task_command.py:423} INFO - Running <TaskInstance: fetch_data_files.get_files_3 scheduled__2016-01-29T00:00:00+00:00 [running]> on host eb03c8b8b5fd
[2024-03-03T03:15:36.964+0000] {taskinstance.py:2510} INFO - Exporting env vars: AIRFLOW_CTX_DAG_OWNER='***' AIRFLOW_CTX_DAG_ID='fetch_data_files' AIRFLOW_CTX_TASK_ID='get_files_3' AIRFLOW_CTX_EXECUTION_DATE='2016-01-29T00:00:00+00:00' AIRFLOW_CTX_TRY_NUMBER='1' AIRFLOW_CTX_DAG_RUN_ID='scheduled__2016-01-29T00:00:00+00:00'
[2024-03-03T03:15:38.286+0000] {taskinstance.py:2728} ERROR - Task failed with exception
Traceback (most recent call last):
  File "/home/airflow/.local/lib/python3.11/site-packages/airflow/models/taskinstance.py", line 444, in _execute_task
    result = _execute_callable(context=context, **execute_callable_kwargs)
             ^^^^^^^^^^^^^^^^^^^^^^^^^^^^^^^^^^^^^^^^^^^^^^^^^^^^^^^^^^^^^
  File "/home/airflow/.local/lib/python3.11/site-packages/airflow/models/taskinstance.py", line 414, in _execute_callable
    return execute_callable(context=context, **execute_callable_kwargs)
           ^^^^^^^^^^^^^^^^^^^^^^^^^^^^^^^^^^^^^^^^^^^^^^^^^^^^^^^^^^^^
  File "/home/airflow/.local/lib/python3.11/site-packages/airflow/operators/python.py", line 200, in execute
    return_value = self.execute_callable()
                   ^^^^^^^^^^^^^^^^^^^^^^^
  File "/home/airflow/.local/lib/python3.11/site-packages/airflow/operators/python.py", line 217, in execute_callable
    return self.python_callable(*self.op_args, **self.op_kwargs)
           ^^^^^^^^^^^^^^^^^^^^^^^^^^^^^^^^^^^^^^^^^^^^^^^^^^^^^
  File "/opt/airflow/dags/dummy_dag.py", line 29, in download_years_list
    page = urlopen(url)
           ^^^^^^^^^^^^
  File "/usr/local/lib/python3.11/urllib/request.py", line 216, in urlopen
    return opener.open(url, data, timeout)
           ^^^^^^^^^^^^^^^^^^^^^^^^^^^^^^^
  File "/usr/local/lib/python3.11/urllib/request.py", line 525, in open
    response = meth(req, response)
               ^^^^^^^^^^^^^^^^^^^
  File "/usr/local/lib/python3.11/urllib/request.py", line 634, in http_response
    response = self.parent.error(
               ^^^^^^^^^^^^^^^^^^
  File "/usr/local/lib/python3.11/urllib/request.py", line 563, in error
    return self._call_chain(*args)
           ^^^^^^^^^^^^^^^^^^^^^^^
  File "/usr/local/lib/python3.11/urllib/request.py", line 496, in _call_chain
    result = func(*args)
             ^^^^^^^^^^^
  File "/usr/local/lib/python3.11/urllib/request.py", line 643, in http_error_default
    raise HTTPError(req.full_url, code, msg, hdrs, fp)
urllib.error.HTTPError: HTTP Error 404: Not Found
[2024-03-03T03:15:38.395+0000] {taskinstance.py:1149} INFO - Marking task as FAILED. dag_id=fetch_data_files, task_id=get_files_3, execution_date=20160129T000000, start_date=20240303T031536, end_date=20240303T031538
[2024-03-03T03:15:38.490+0000] {standard_task_runner.py:107} ERROR - Failed to execute job 185 for task get_files_3 (HTTP Error 404: Not Found; 608)
[2024-03-03T03:15:38.553+0000] {local_task_job_runner.py:234} INFO - Task exited with return code 1
[2024-03-03T03:15:38.638+0000] {taskinstance.py:3309} INFO - 0 downstream tasks scheduled from follow-on schedule check
[2024-03-03T03:30:13.404+0000] {taskinstance.py:1979} INFO - Dependencies all met for dep_context=non-requeueable deps ti=<TaskInstance: fetch_data_files.get_files_3 scheduled__2016-01-29T00:00:00+00:00 [queued]>
[2024-03-03T03:30:13.421+0000] {taskinstance.py:1979} INFO - Dependencies all met for dep_context=requeueable deps ti=<TaskInstance: fetch_data_files.get_files_3 scheduled__2016-01-29T00:00:00+00:00 [queued]>
[2024-03-03T03:30:13.422+0000] {taskinstance.py:2193} INFO - Starting attempt 1 of 1
[2024-03-03T03:30:13.448+0000] {taskinstance.py:2214} INFO - Executing <Task(PythonOperator): get_files_3> on 2016-01-29 00:00:00+00:00
[2024-03-03T03:30:13.458+0000] {standard_task_runner.py:60} INFO - Started process 633 to run task
[2024-03-03T03:30:13.461+0000] {standard_task_runner.py:87} INFO - Running: ['***', 'tasks', 'run', 'fetch_data_files', 'get_files_3', 'scheduled__2016-01-29T00:00:00+00:00', '--job-id', '176', '--raw', '--subdir', 'DAGS_FOLDER/dummy_dag.py', '--cfg-path', '/tmp/tmpk1lbf2gd']
[2024-03-03T03:30:13.465+0000] {standard_task_runner.py:88} INFO - Job 176: Subtask get_files_3
[2024-03-03T03:30:13.500+0000] {logging_mixin.py:188} WARNING - /home/***/.local/lib/python3.11/site-packages/***/settings.py:194 DeprecationWarning: The sql_alchemy_conn option in [core] has been moved to the sql_alchemy_conn option in [database] - the old setting has been used, but please update your config.
[2024-03-03T03:30:13.577+0000] {task_command.py:423} INFO - Running <TaskInstance: fetch_data_files.get_files_3 scheduled__2016-01-29T00:00:00+00:00 [running]> on host 716a53fa82e1
[2024-03-03T03:30:13.725+0000] {taskinstance.py:2510} INFO - Exporting env vars: AIRFLOW_CTX_DAG_OWNER='***' AIRFLOW_CTX_DAG_ID='fetch_data_files' AIRFLOW_CTX_TASK_ID='get_files_3' AIRFLOW_CTX_EXECUTION_DATE='2016-01-29T00:00:00+00:00' AIRFLOW_CTX_TRY_NUMBER='1' AIRFLOW_CTX_DAG_RUN_ID='scheduled__2016-01-29T00:00:00+00:00'
[2024-03-03T03:30:15.681+0000] {taskinstance.py:2728} ERROR - Task failed with exception
Traceback (most recent call last):
  File "/home/airflow/.local/lib/python3.11/site-packages/airflow/models/taskinstance.py", line 444, in _execute_task
    result = _execute_callable(context=context, **execute_callable_kwargs)
             ^^^^^^^^^^^^^^^^^^^^^^^^^^^^^^^^^^^^^^^^^^^^^^^^^^^^^^^^^^^^^
  File "/home/airflow/.local/lib/python3.11/site-packages/airflow/models/taskinstance.py", line 414, in _execute_callable
    return execute_callable(context=context, **execute_callable_kwargs)
           ^^^^^^^^^^^^^^^^^^^^^^^^^^^^^^^^^^^^^^^^^^^^^^^^^^^^^^^^^^^^
  File "/home/airflow/.local/lib/python3.11/site-packages/airflow/operators/python.py", line 200, in execute
    return_value = self.execute_callable()
                   ^^^^^^^^^^^^^^^^^^^^^^^
  File "/home/airflow/.local/lib/python3.11/site-packages/airflow/operators/python.py", line 217, in execute_callable
    return self.python_callable(*self.op_args, **self.op_kwargs)
           ^^^^^^^^^^^^^^^^^^^^^^^^^^^^^^^^^^^^^^^^^^^^^^^^^^^^^
  File "/opt/airflow/dags/dummy_dag.py", line 30, in download_years_list
    page = urlopen(url)
           ^^^^^^^^^^^^
  File "/usr/local/lib/python3.11/urllib/request.py", line 216, in urlopen
    return opener.open(url, data, timeout)
           ^^^^^^^^^^^^^^^^^^^^^^^^^^^^^^^
  File "/usr/local/lib/python3.11/urllib/request.py", line 525, in open
    response = meth(req, response)
               ^^^^^^^^^^^^^^^^^^^
  File "/usr/local/lib/python3.11/urllib/request.py", line 634, in http_response
    response = self.parent.error(
               ^^^^^^^^^^^^^^^^^^
  File "/usr/local/lib/python3.11/urllib/request.py", line 563, in error
    return self._call_chain(*args)
           ^^^^^^^^^^^^^^^^^^^^^^^
  File "/usr/local/lib/python3.11/urllib/request.py", line 496, in _call_chain
    result = func(*args)
             ^^^^^^^^^^^
  File "/usr/local/lib/python3.11/urllib/request.py", line 643, in http_error_default
    raise HTTPError(req.full_url, code, msg, hdrs, fp)
urllib.error.HTTPError: HTTP Error 404: Not Found
[2024-03-03T03:30:15.714+0000] {taskinstance.py:1149} INFO - Marking task as FAILED. dag_id=fetch_data_files, task_id=get_files_3, execution_date=20160129T000000, start_date=20240303T033013, end_date=20240303T033015
[2024-03-03T03:30:15.746+0000] {standard_task_runner.py:107} ERROR - Failed to execute job 176 for task get_files_3 (HTTP Error 404: Not Found; 633)
[2024-03-03T03:30:15.807+0000] {local_task_job_runner.py:234} INFO - Task exited with return code 1
[2024-03-03T03:30:15.843+0000] {taskinstance.py:3309} INFO - 0 downstream tasks scheduled from follow-on schedule check
