[2024-03-10T16:20:36.424+0000] {taskinstance.py:1979} INFO - Dependencies all met for dep_context=non-requeueable deps ti=<TaskInstance: processing.Create_images_3 manual__2024-03-10T16:20:11.056179+00:00 [queued]>
[2024-03-10T16:20:36.458+0000] {taskinstance.py:1979} INFO - Dependencies all met for dep_context=requeueable deps ti=<TaskInstance: processing.Create_images_3 manual__2024-03-10T16:20:11.056179+00:00 [queued]>
[2024-03-10T16:20:36.460+0000] {taskinstance.py:2193} INFO - Starting attempt 1 of 1
[2024-03-10T16:20:36.497+0000] {taskinstance.py:2214} INFO - Executing <Task(PythonOperator): Create_images_3> on 2024-03-10 16:20:11.056179+00:00
[2024-03-10T16:20:36.521+0000] {standard_task_runner.py:60} INFO - Started process 362 to run task
[2024-03-10T16:20:36.562+0000] {standard_task_runner.py:87} INFO - Running: ['***', 'tasks', 'run', 'processing', 'Create_images_3', 'manual__2024-03-10T16:20:11.056179+00:00', '--job-id', '13', '--raw', '--subdir', 'DAGS_FOLDER/process_data.py', '--cfg-path', '/tmp/tmpwakxuz46']
[2024-03-10T16:20:36.600+0000] {standard_task_runner.py:88} INFO - Job 13: Subtask Create_images_3
[2024-03-10T16:20:36.738+0000] {logging_mixin.py:188} WARNING - /home/***/.local/lib/python3.11/site-packages/***/settings.py:194 DeprecationWarning: The sql_alchemy_conn option in [core] has been moved to the sql_alchemy_conn option in [database] - the old setting has been used, but please update your config.
[2024-03-10T16:20:36.860+0000] {task_command.py:423} INFO - Running <TaskInstance: processing.Create_images_3 manual__2024-03-10T16:20:11.056179+00:00 [running]> on host 65d624ba7e11
[2024-03-10T16:20:37.027+0000] {taskinstance.py:2510} INFO - Exporting env vars: AIRFLOW_CTX_DAG_OWNER='***' AIRFLOW_CTX_DAG_ID='processing' AIRFLOW_CTX_TASK_ID='Create_images_3' AIRFLOW_CTX_EXECUTION_DATE='2024-03-10T16:20:11.056179+00:00' AIRFLOW_CTX_TRY_NUMBER='1' AIRFLOW_CTX_DAG_RUN_ID='manual__2024-03-10T16:20:11.056179+00:00'
[2024-03-10T16:20:37.065+0000] {taskinstance.py:2728} ERROR - Task failed with exception
Traceback (most recent call last):
  File "/home/airflow/.local/lib/python3.11/site-packages/airflow/models/taskinstance.py", line 444, in _execute_task
    result = _execute_callable(context=context, **execute_callable_kwargs)
             ^^^^^^^^^^^^^^^^^^^^^^^^^^^^^^^^^^^^^^^^^^^^^^^^^^^^^^^^^^^^^
  File "/home/airflow/.local/lib/python3.11/site-packages/airflow/models/taskinstance.py", line 414, in _execute_callable
    return execute_callable(context=context, **execute_callable_kwargs)
           ^^^^^^^^^^^^^^^^^^^^^^^^^^^^^^^^^^^^^^^^^^^^^^^^^^^^^^^^^^^^
  File "/home/airflow/.local/lib/python3.11/site-packages/airflow/operators/python.py", line 200, in execute
    return_value = self.execute_callable()
                   ^^^^^^^^^^^^^^^^^^^^^^^
  File "/home/airflow/.local/lib/python3.11/site-packages/airflow/operators/python.py", line 217, in execute_callable
    return self.python_callable(*self.op_args, **self.op_kwargs)
           ^^^^^^^^^^^^^^^^^^^^^^^^^^^^^^^^^^^^^^^^^^^^^^^^^^^^^
  File "/opt/airflow/dags/process_data.py", line 91, in map_maker
    for num in range(1,13):
               ^^^^^
UnboundLocalError: cannot access local variable 'range' where it is not associated with a value
[2024-03-10T16:20:37.094+0000] {taskinstance.py:1149} INFO - Marking task as FAILED. dag_id=processing, task_id=Create_images_3, execution_date=20240310T162011, start_date=20240310T162036, end_date=20240310T162037
[2024-03-10T16:20:37.136+0000] {standard_task_runner.py:107} ERROR - Failed to execute job 13 for task Create_images_3 (cannot access local variable 'range' where it is not associated with a value; 362)
[2024-03-10T16:20:37.151+0000] {local_task_job_runner.py:234} INFO - Task exited with return code 1
[2024-03-10T16:20:37.200+0000] {taskinstance.py:3309} INFO - 0 downstream tasks scheduled from follow-on schedule check
