[2024-03-03T03:07:11.495+0000] {taskinstance.py:1979} INFO - Dependencies all met for dep_context=non-requeueable deps ti=<TaskInstance: fetch_data_files.get_files_1 scheduled__2019-10-10T00:00:00+00:00 [queued]>
[2024-03-03T03:07:11.510+0000] {taskinstance.py:1979} INFO - Dependencies all met for dep_context=requeueable deps ti=<TaskInstance: fetch_data_files.get_files_1 scheduled__2019-10-10T00:00:00+00:00 [queued]>
[2024-03-03T03:07:11.511+0000] {taskinstance.py:2193} INFO - Starting attempt 1 of 1
[2024-03-03T03:07:11.536+0000] {taskinstance.py:2214} INFO - Executing <Task(PythonOperator): get_files_1> on 2019-10-10 00:00:00+00:00
[2024-03-03T03:07:11.546+0000] {standard_task_runner.py:60} INFO - Started process 5337 to run task
[2024-03-03T03:07:11.550+0000] {standard_task_runner.py:87} INFO - Running: ['***', 'tasks', 'run', 'fetch_data_files', 'get_files_1', 'scheduled__2019-10-10T00:00:00+00:00', '--job-id', '5317', '--raw', '--subdir', 'DAGS_FOLDER/dummy_dag.py', '--cfg-path', '/tmp/tmp5fiagnvt']
[2024-03-03T03:07:11.555+0000] {standard_task_runner.py:88} INFO - Job 5317: Subtask get_files_1
[2024-03-03T03:07:11.586+0000] {logging_mixin.py:188} WARNING - /home/***/.local/lib/python3.11/site-packages/***/settings.py:194 DeprecationWarning: The sql_alchemy_conn option in [core] has been moved to the sql_alchemy_conn option in [database] - the old setting has been used, but please update your config.
[2024-03-03T03:07:11.662+0000] {task_command.py:423} INFO - Running <TaskInstance: fetch_data_files.get_files_1 scheduled__2019-10-10T00:00:00+00:00 [running]> on host 887b52fd1a6d
[2024-03-03T03:07:11.830+0000] {taskinstance.py:2510} INFO - Exporting env vars: AIRFLOW_CTX_DAG_OWNER='***' AIRFLOW_CTX_DAG_ID='fetch_data_files' AIRFLOW_CTX_TASK_ID='get_files_1' AIRFLOW_CTX_EXECUTION_DATE='2019-10-10T00:00:00+00:00' AIRFLOW_CTX_TRY_NUMBER='1' AIRFLOW_CTX_DAG_RUN_ID='scheduled__2019-10-10T00:00:00+00:00'
[2024-03-03T03:07:13.011+0000] {taskinstance.py:2728} ERROR - Task failed with exception
Traceback (most recent call last):
  File "/home/airflow/.local/lib/python3.11/site-packages/airflow/models/taskinstance.py", line 444, in _execute_task
    result = _execute_callable(context=context, **execute_callable_kwargs)
             ^^^^^^^^^^^^^^^^^^^^^^^^^^^^^^^^^^^^^^^^^^^^^^^^^^^^^^^^^^^^^
  File "/home/airflow/.local/lib/python3.11/site-packages/airflow/models/taskinstance.py", line 414, in _execute_callable
    return execute_callable(context=context, **execute_callable_kwargs)
           ^^^^^^^^^^^^^^^^^^^^^^^^^^^^^^^^^^^^^^^^^^^^^^^^^^^^^^^^^^^^
  File "/home/airflow/.local/lib/python3.11/site-packages/airflow/operators/python.py", line 200, in execute
    return_value = self.execute_callable()
                   ^^^^^^^^^^^^^^^^^^^^^^^
  File "/home/airflow/.local/lib/python3.11/site-packages/airflow/operators/python.py", line 217, in execute_callable
    return self.python_callable(*self.op_args, **self.op_kwargs)
           ^^^^^^^^^^^^^^^^^^^^^^^^^^^^^^^^^^^^^^^^^^^^^^^^^^^^^
  File "/opt/airflow/dags/dummy_dag.py", line 29, in download_years_list
    page = urlopen(url)
           ^^^^^^^^^^^^
  File "/usr/local/lib/python3.11/urllib/request.py", line 216, in urlopen
    return opener.open(url, data, timeout)
           ^^^^^^^^^^^^^^^^^^^^^^^^^^^^^^^
  File "/usr/local/lib/python3.11/urllib/request.py", line 525, in open
    response = meth(req, response)
               ^^^^^^^^^^^^^^^^^^^
  File "/usr/local/lib/python3.11/urllib/request.py", line 634, in http_response
    response = self.parent.error(
               ^^^^^^^^^^^^^^^^^^
  File "/usr/local/lib/python3.11/urllib/request.py", line 563, in error
    return self._call_chain(*args)
           ^^^^^^^^^^^^^^^^^^^^^^^
  File "/usr/local/lib/python3.11/urllib/request.py", line 496, in _call_chain
    result = func(*args)
             ^^^^^^^^^^^
  File "/usr/local/lib/python3.11/urllib/request.py", line 643, in http_error_default
    raise HTTPError(req.full_url, code, msg, hdrs, fp)
urllib.error.HTTPError: HTTP Error 404: Not Found
[2024-03-03T03:07:13.144+0000] {taskinstance.py:1149} INFO - Marking task as FAILED. dag_id=fetch_data_files, task_id=get_files_1, execution_date=20191010T000000, start_date=20240303T030711, end_date=20240303T030713
[2024-03-03T03:07:13.163+0000] {standard_task_runner.py:107} ERROR - Failed to execute job 5317 for task get_files_1 (HTTP Error 404: Not Found; 5337)
[2024-03-03T03:07:13.215+0000] {local_task_job_runner.py:234} INFO - Task exited with return code 1
[2024-03-03T03:07:13.298+0000] {taskinstance.py:3309} INFO - 0 downstream tasks scheduled from follow-on schedule check
