[2024-03-03T03:02:46.871+0000] {taskinstance.py:1979} INFO - Dependencies all met for dep_context=non-requeueable deps ti=<TaskInstance: fetch_data_files.get_files_4 scheduled__2019-04-19T00:00:00+00:00 [queued]>
[2024-03-03T03:02:46.886+0000] {taskinstance.py:1979} INFO - Dependencies all met for dep_context=requeueable deps ti=<TaskInstance: fetch_data_files.get_files_4 scheduled__2019-04-19T00:00:00+00:00 [queued]>
[2024-03-03T03:02:46.888+0000] {taskinstance.py:2193} INFO - Starting attempt 1 of 1
[2024-03-03T03:02:46.918+0000] {taskinstance.py:2214} INFO - Executing <Task(PythonOperator): get_files_4> on 2019-04-19 00:00:00+00:00
[2024-03-03T03:02:46.929+0000] {standard_task_runner.py:60} INFO - Started process 3200 to run task
[2024-03-03T03:02:46.935+0000] {standard_task_runner.py:87} INFO - Running: ['***', 'tasks', 'run', 'fetch_data_files', 'get_files_4', 'scheduled__2019-04-19T00:00:00+00:00', '--job-id', '4271', '--raw', '--subdir', 'DAGS_FOLDER/dummy_dag.py', '--cfg-path', '/tmp/tmp_407wy3x']
[2024-03-03T03:02:46.943+0000] {standard_task_runner.py:88} INFO - Job 4271: Subtask get_files_4
[2024-03-03T03:02:47.112+0000] {logging_mixin.py:188} WARNING - /home/***/.local/lib/python3.11/site-packages/***/settings.py:194 DeprecationWarning: The sql_alchemy_conn option in [core] has been moved to the sql_alchemy_conn option in [database] - the old setting has been used, but please update your config.
[2024-03-03T03:02:47.327+0000] {task_command.py:423} INFO - Running <TaskInstance: fetch_data_files.get_files_4 scheduled__2019-04-19T00:00:00+00:00 [running]> on host 887b52fd1a6d
[2024-03-03T03:02:47.544+0000] {taskinstance.py:2510} INFO - Exporting env vars: AIRFLOW_CTX_DAG_OWNER='***' AIRFLOW_CTX_DAG_ID='fetch_data_files' AIRFLOW_CTX_TASK_ID='get_files_4' AIRFLOW_CTX_EXECUTION_DATE='2019-04-19T00:00:00+00:00' AIRFLOW_CTX_TRY_NUMBER='1' AIRFLOW_CTX_DAG_RUN_ID='scheduled__2019-04-19T00:00:00+00:00'
[2024-03-03T03:02:48.804+0000] {taskinstance.py:2728} ERROR - Task failed with exception
Traceback (most recent call last):
  File "/home/airflow/.local/lib/python3.11/site-packages/airflow/models/taskinstance.py", line 444, in _execute_task
    result = _execute_callable(context=context, **execute_callable_kwargs)
             ^^^^^^^^^^^^^^^^^^^^^^^^^^^^^^^^^^^^^^^^^^^^^^^^^^^^^^^^^^^^^
  File "/home/airflow/.local/lib/python3.11/site-packages/airflow/models/taskinstance.py", line 414, in _execute_callable
    return execute_callable(context=context, **execute_callable_kwargs)
           ^^^^^^^^^^^^^^^^^^^^^^^^^^^^^^^^^^^^^^^^^^^^^^^^^^^^^^^^^^^^
  File "/home/airflow/.local/lib/python3.11/site-packages/airflow/operators/python.py", line 200, in execute
    return_value = self.execute_callable()
                   ^^^^^^^^^^^^^^^^^^^^^^^
  File "/home/airflow/.local/lib/python3.11/site-packages/airflow/operators/python.py", line 217, in execute_callable
    return self.python_callable(*self.op_args, **self.op_kwargs)
           ^^^^^^^^^^^^^^^^^^^^^^^^^^^^^^^^^^^^^^^^^^^^^^^^^^^^^
  File "/opt/airflow/dags/dummy_dag.py", line 29, in download_years_list
    page = urlopen(url)
           ^^^^^^^^^^^^
  File "/usr/local/lib/python3.11/urllib/request.py", line 216, in urlopen
    return opener.open(url, data, timeout)
           ^^^^^^^^^^^^^^^^^^^^^^^^^^^^^^^
  File "/usr/local/lib/python3.11/urllib/request.py", line 525, in open
    response = meth(req, response)
               ^^^^^^^^^^^^^^^^^^^
  File "/usr/local/lib/python3.11/urllib/request.py", line 634, in http_response
    response = self.parent.error(
               ^^^^^^^^^^^^^^^^^^
  File "/usr/local/lib/python3.11/urllib/request.py", line 563, in error
    return self._call_chain(*args)
           ^^^^^^^^^^^^^^^^^^^^^^^
  File "/usr/local/lib/python3.11/urllib/request.py", line 496, in _call_chain
    result = func(*args)
             ^^^^^^^^^^^
  File "/usr/local/lib/python3.11/urllib/request.py", line 643, in http_error_default
    raise HTTPError(req.full_url, code, msg, hdrs, fp)
urllib.error.HTTPError: HTTP Error 404: Not Found
[2024-03-03T03:02:48.830+0000] {taskinstance.py:1149} INFO - Marking task as FAILED. dag_id=fetch_data_files, task_id=get_files_4, execution_date=20190419T000000, start_date=20240303T030246, end_date=20240303T030248
[2024-03-03T03:02:48.845+0000] {standard_task_runner.py:107} ERROR - Failed to execute job 4271 for task get_files_4 (HTTP Error 404: Not Found; 3200)
[2024-03-03T03:02:48.896+0000] {local_task_job_runner.py:234} INFO - Task exited with return code 1
[2024-03-03T03:02:48.920+0000] {taskinstance.py:3309} INFO - 0 downstream tasks scheduled from follow-on schedule check
