[2024-03-03T02:49:15.693+0000] {taskinstance.py:1979} INFO - Dependencies all met for dep_context=non-requeueable deps ti=<TaskInstance: fetch_data_files.get_files scheduled__2018-09-16T00:00:00+00:00 [queued]>
[2024-03-03T02:49:15.706+0000] {taskinstance.py:1979} INFO - Dependencies all met for dep_context=requeueable deps ti=<TaskInstance: fetch_data_files.get_files scheduled__2018-09-16T00:00:00+00:00 [queued]>
[2024-03-03T02:49:15.707+0000] {taskinstance.py:2193} INFO - Starting attempt 1 of 1
[2024-03-03T02:49:15.746+0000] {taskinstance.py:2214} INFO - Executing <Task(PythonOperator): get_files> on 2018-09-16 00:00:00+00:00
[2024-03-03T02:49:15.755+0000] {standard_task_runner.py:60} INFO - Started process 2482 to run task
[2024-03-03T02:49:15.762+0000] {standard_task_runner.py:87} INFO - Running: ['***', 'tasks', 'run', 'fetch_data_files', 'get_files', 'scheduled__2018-09-16T00:00:00+00:00', '--job-id', '3985', '--raw', '--subdir', 'DAGS_FOLDER/dummy_dag.py', '--cfg-path', '/tmp/tmpkoojbopx']
[2024-03-03T02:49:15.767+0000] {standard_task_runner.py:88} INFO - Job 3985: Subtask get_files
[2024-03-03T02:49:15.791+0000] {logging_mixin.py:188} WARNING - /home/***/.local/lib/python3.11/site-packages/***/settings.py:194 DeprecationWarning: The sql_alchemy_conn option in [core] has been moved to the sql_alchemy_conn option in [database] - the old setting has been used, but please update your config.
[2024-03-03T02:49:15.854+0000] {task_command.py:423} INFO - Running <TaskInstance: fetch_data_files.get_files scheduled__2018-09-16T00:00:00+00:00 [running]> on host 887b52fd1a6d
[2024-03-03T02:49:15.979+0000] {taskinstance.py:2510} INFO - Exporting env vars: AIRFLOW_CTX_DAG_OWNER='***' AIRFLOW_CTX_DAG_ID='fetch_data_files' AIRFLOW_CTX_TASK_ID='get_files' AIRFLOW_CTX_EXECUTION_DATE='2018-09-16T00:00:00+00:00' AIRFLOW_CTX_TRY_NUMBER='1' AIRFLOW_CTX_DAG_RUN_ID='scheduled__2018-09-16T00:00:00+00:00'
[2024-03-03T02:49:18.240+0000] {taskinstance.py:2728} ERROR - Task failed with exception
Traceback (most recent call last):
  File "/home/airflow/.local/lib/python3.11/site-packages/airflow/models/taskinstance.py", line 444, in _execute_task
    result = _execute_callable(context=context, **execute_callable_kwargs)
             ^^^^^^^^^^^^^^^^^^^^^^^^^^^^^^^^^^^^^^^^^^^^^^^^^^^^^^^^^^^^^
  File "/home/airflow/.local/lib/python3.11/site-packages/airflow/models/taskinstance.py", line 414, in _execute_callable
    return execute_callable(context=context, **execute_callable_kwargs)
           ^^^^^^^^^^^^^^^^^^^^^^^^^^^^^^^^^^^^^^^^^^^^^^^^^^^^^^^^^^^^
  File "/home/airflow/.local/lib/python3.11/site-packages/airflow/operators/python.py", line 200, in execute
    return_value = self.execute_callable()
                   ^^^^^^^^^^^^^^^^^^^^^^^
  File "/home/airflow/.local/lib/python3.11/site-packages/airflow/operators/python.py", line 217, in execute_callable
    return self.python_callable(*self.op_args, **self.op_kwargs)
           ^^^^^^^^^^^^^^^^^^^^^^^^^^^^^^^^^^^^^^^^^^^^^^^^^^^^^
  File "/opt/airflow/dags/dummy_dag.py", line 40, in download_years_list
    urlretrieve(files[i],f'/opt/airflow/Files/Files/{l}/{x[i]}')
  File "/usr/local/lib/python3.11/urllib/request.py", line 251, in urlretrieve
    tfp = open(filename, 'wb')
          ^^^^^^^^^^^^^^^^^^^^
FileNotFoundError: [Errno 2] No such file or directory: '/opt/airflow/Files/Files/1901/02907099999.csv'
[2024-03-03T02:49:18.261+0000] {taskinstance.py:1149} INFO - Marking task as FAILED. dag_id=fetch_data_files, task_id=get_files, execution_date=20180916T000000, start_date=20240303T024915, end_date=20240303T024918
[2024-03-03T02:49:18.279+0000] {standard_task_runner.py:107} ERROR - Failed to execute job 3985 for task get_files ([Errno 2] No such file or directory: '/opt/airflow/Files/Files/1901/02907099999.csv'; 2482)
[2024-03-03T02:49:18.304+0000] {local_task_job_runner.py:234} INFO - Task exited with return code 1
[2024-03-03T02:49:18.331+0000] {taskinstance.py:3309} INFO - 0 downstream tasks scheduled from follow-on schedule check
