[2024-03-03T02:50:43.552+0000] {taskinstance.py:1979} INFO - Dependencies all met for dep_context=non-requeueable deps ti=<TaskInstance: fetch_data_files.get_files scheduled__2019-03-18T00:00:00+00:00 [queued]>
[2024-03-03T02:50:43.563+0000] {taskinstance.py:1979} INFO - Dependencies all met for dep_context=requeueable deps ti=<TaskInstance: fetch_data_files.get_files scheduled__2019-03-18T00:00:00+00:00 [queued]>
[2024-03-03T02:50:43.563+0000] {taskinstance.py:2193} INFO - Starting attempt 1 of 1
[2024-03-03T02:50:43.595+0000] {taskinstance.py:2214} INFO - Executing <Task(PythonOperator): get_files> on 2019-03-18 00:00:00+00:00
[2024-03-03T02:50:43.603+0000] {standard_task_runner.py:60} INFO - Started process 2866 to run task
[2024-03-03T02:50:43.606+0000] {standard_task_runner.py:87} INFO - Running: ['***', 'tasks', 'run', 'fetch_data_files', 'get_files', 'scheduled__2019-03-18T00:00:00+00:00', '--job-id', '4168', '--raw', '--subdir', 'DAGS_FOLDER/dummy_dag.py', '--cfg-path', '/tmp/tmpn1x9z8fs']
[2024-03-03T02:50:43.610+0000] {standard_task_runner.py:88} INFO - Job 4168: Subtask get_files
[2024-03-03T02:50:43.634+0000] {logging_mixin.py:188} WARNING - /home/***/.local/lib/python3.11/site-packages/***/settings.py:194 DeprecationWarning: The sql_alchemy_conn option in [core] has been moved to the sql_alchemy_conn option in [database] - the old setting has been used, but please update your config.
[2024-03-03T02:50:43.693+0000] {task_command.py:423} INFO - Running <TaskInstance: fetch_data_files.get_files scheduled__2019-03-18T00:00:00+00:00 [running]> on host 887b52fd1a6d
[2024-03-03T02:50:43.801+0000] {taskinstance.py:2510} INFO - Exporting env vars: AIRFLOW_CTX_DAG_OWNER='***' AIRFLOW_CTX_DAG_ID='fetch_data_files' AIRFLOW_CTX_TASK_ID='get_files' AIRFLOW_CTX_EXECUTION_DATE='2019-03-18T00:00:00+00:00' AIRFLOW_CTX_TRY_NUMBER='1' AIRFLOW_CTX_DAG_RUN_ID='scheduled__2019-03-18T00:00:00+00:00'
[2024-03-03T02:51:18.963+0000] {local_task_job_runner.py:302} WARNING - State of this instance has been externally set to None. Terminating instance.
[2024-03-03T02:51:18.966+0000] {process_utils.py:131} INFO - Sending 15 to group 2866. PIDs of all processes in the group: [2866]
[2024-03-03T02:51:18.967+0000] {process_utils.py:86} INFO - Sending the signal 15 to group 2866
[2024-03-03T02:51:18.968+0000] {taskinstance.py:2480} ERROR - Received SIGTERM. Terminating subprocesses.
[2024-03-03T02:51:18.983+0000] {taskinstance.py:2728} ERROR - Task failed with exception
Traceback (most recent call last):
  File "/home/airflow/.local/lib/python3.11/site-packages/airflow/models/taskinstance.py", line 444, in _execute_task
    result = _execute_callable(context=context, **execute_callable_kwargs)
             ^^^^^^^^^^^^^^^^^^^^^^^^^^^^^^^^^^^^^^^^^^^^^^^^^^^^^^^^^^^^^
  File "/home/airflow/.local/lib/python3.11/site-packages/airflow/models/taskinstance.py", line 414, in _execute_callable
    return execute_callable(context=context, **execute_callable_kwargs)
           ^^^^^^^^^^^^^^^^^^^^^^^^^^^^^^^^^^^^^^^^^^^^^^^^^^^^^^^^^^^^
  File "/home/airflow/.local/lib/python3.11/site-packages/airflow/operators/python.py", line 200, in execute
    return_value = self.execute_callable()
                   ^^^^^^^^^^^^^^^^^^^^^^^
  File "/home/airflow/.local/lib/python3.11/site-packages/airflow/operators/python.py", line 217, in execute_callable
    return self.python_callable(*self.op_args, **self.op_kwargs)
           ^^^^^^^^^^^^^^^^^^^^^^^^^^^^^^^^^^^^^^^^^^^^^^^^^^^^^
  File "/opt/airflow/dags/dummy_dag.py", line 45, in download_years_list
    urlretrieve(files[i],f'/opt/airflow/Files/Files/{l}/{x[i]}')
  File "/usr/local/lib/python3.11/urllib/request.py", line 270, in urlretrieve
    block = fp.read(bs)
            ^^^^^^^^^^^
  File "/usr/local/lib/python3.11/http/client.py", line 473, in read
    s = self.fp.read(amt)
        ^^^^^^^^^^^^^^^^^
  File "/usr/local/lib/python3.11/socket.py", line 706, in readinto
    return self._sock.recv_into(b)
           ^^^^^^^^^^^^^^^^^^^^^^^
  File "/usr/local/lib/python3.11/ssl.py", line 1314, in recv_into
    return self.read(nbytes, buffer)
           ^^^^^^^^^^^^^^^^^^^^^^^^^
  File "/usr/local/lib/python3.11/ssl.py", line 1166, in read
    return self._sslobj.read(len, buffer)
           ^^^^^^^^^^^^^^^^^^^^^^^^^^^^^^
  File "/home/airflow/.local/lib/python3.11/site-packages/airflow/models/taskinstance.py", line 2482, in signal_handler
    raise AirflowException("Task received SIGTERM signal")
airflow.exceptions.AirflowException: Task received SIGTERM signal
[2024-03-03T02:51:18.998+0000] {taskinstance.py:1149} INFO - Marking task as FAILED. dag_id=fetch_data_files, task_id=get_files, execution_date=20190318T000000, start_date=20240303T025043, end_date=20240303T025118
[2024-03-03T02:51:19.019+0000] {standard_task_runner.py:107} ERROR - Failed to execute job 4168 for task get_files ((psycopg2.errors.ForeignKeyViolation) insert or update on table "task_fail" violates foreign key constraint "task_fail_ti_fkey"
DETAIL:  Key (dag_id, task_id, run_id, map_index)=(fetch_data_files, get_files, scheduled__2019-03-18T00:00:00+00:00, -1) is not present in table "task_instance".

[SQL: INSERT INTO task_fail (task_id, dag_id, run_id, map_index, start_date, end_date, duration) VALUES (%(task_id)s, %(dag_id)s, %(run_id)s, %(map_index)s, %(start_date)s, %(end_date)s, %(duration)s) RETURNING task_fail.id]
[parameters: {'task_id': 'get_files', 'dag_id': 'fetch_data_files', 'run_id': 'scheduled__2019-03-18T00:00:00+00:00', 'map_index': -1, 'start_date': datetime.datetime(2024, 3, 3, 2, 50, 43, 553469, tzinfo=Timezone('UTC')), 'end_date': datetime.datetime(2024, 3, 3, 2, 51, 18, 997273, tzinfo=Timezone('UTC')), 'duration': 35}]
(Background on this error at: https://sqlalche.me/e/14/gkpj); 2866)
[2024-03-03T02:51:19.060+0000] {process_utils.py:79} INFO - Process psutil.Process(pid=2866, status='terminated', exitcode=1, started='02:50:43') (2866) terminated with exit code 1
[2024-03-03T02:51:31.324+0000] {taskinstance.py:1979} INFO - Dependencies all met for dep_context=non-requeueable deps ti=<TaskInstance: fetch_data_files.get_files scheduled__2019-03-18T00:00:00+00:00 [queued]>
[2024-03-03T02:51:31.337+0000] {taskinstance.py:1979} INFO - Dependencies all met for dep_context=requeueable deps ti=<TaskInstance: fetch_data_files.get_files scheduled__2019-03-18T00:00:00+00:00 [queued]>
[2024-03-03T02:51:31.338+0000] {taskinstance.py:2193} INFO - Starting attempt 1 of 1
[2024-03-03T02:51:31.402+0000] {taskinstance.py:2214} INFO - Executing <Task(PythonOperator): get_files> on 2019-03-18 00:00:00+00:00
[2024-03-03T02:51:31.410+0000] {standard_task_runner.py:60} INFO - Started process 2910 to run task
[2024-03-03T02:51:31.418+0000] {standard_task_runner.py:87} INFO - Running: ['***', 'tasks', 'run', 'fetch_data_files', 'get_files', 'scheduled__2019-03-18T00:00:00+00:00', '--job-id', '4185', '--raw', '--subdir', 'DAGS_FOLDER/dummy_dag.py', '--cfg-path', '/tmp/tmp_b3ubh2b']
[2024-03-03T02:51:31.422+0000] {standard_task_runner.py:88} INFO - Job 4185: Subtask get_files
[2024-03-03T02:51:31.444+0000] {logging_mixin.py:188} WARNING - /home/***/.local/lib/python3.11/site-packages/***/settings.py:194 DeprecationWarning: The sql_alchemy_conn option in [core] has been moved to the sql_alchemy_conn option in [database] - the old setting has been used, but please update your config.
[2024-03-03T02:51:31.511+0000] {task_command.py:423} INFO - Running <TaskInstance: fetch_data_files.get_files scheduled__2019-03-18T00:00:00+00:00 [running]> on host 887b52fd1a6d
[2024-03-03T02:51:31.620+0000] {taskinstance.py:2510} INFO - Exporting env vars: AIRFLOW_CTX_DAG_OWNER='***' AIRFLOW_CTX_DAG_ID='fetch_data_files' AIRFLOW_CTX_TASK_ID='get_files' AIRFLOW_CTX_EXECUTION_DATE='2019-03-18T00:00:00+00:00' AIRFLOW_CTX_TRY_NUMBER='1' AIRFLOW_CTX_DAG_RUN_ID='scheduled__2019-03-18T00:00:00+00:00'
[2024-03-03T03:02:06.303+0000] {taskinstance.py:2728} ERROR - Task failed with exception
Traceback (most recent call last):
  File "/home/airflow/.local/lib/python3.11/site-packages/airflow/models/taskinstance.py", line 444, in _execute_task
    result = _execute_callable(context=context, **execute_callable_kwargs)
             ^^^^^^^^^^^^^^^^^^^^^^^^^^^^^^^^^^^^^^^^^^^^^^^^^^^^^^^^^^^^^
  File "/home/airflow/.local/lib/python3.11/site-packages/airflow/models/taskinstance.py", line 414, in _execute_callable
    return execute_callable(context=context, **execute_callable_kwargs)
           ^^^^^^^^^^^^^^^^^^^^^^^^^^^^^^^^^^^^^^^^^^^^^^^^^^^^^^^^^^^^
  File "/home/airflow/.local/lib/python3.11/site-packages/airflow/operators/python.py", line 200, in execute
    return_value = self.execute_callable()
                   ^^^^^^^^^^^^^^^^^^^^^^^
  File "/home/airflow/.local/lib/python3.11/site-packages/airflow/operators/python.py", line 217, in execute_callable
    return self.python_callable(*self.op_args, **self.op_kwargs)
           ^^^^^^^^^^^^^^^^^^^^^^^^^^^^^^^^^^^^^^^^^^^^^^^^^^^^^
  File "/opt/airflow/dags/dummy_dag.py", line 45, in download_years_list
    with DAG('fetch_data_files', start_date=datetime(2016, 1, 1)) as dag:
                    ^^^^^^^^^^^^^^^^^^^^^^^^^^^^^^^^^^^^^^^^^^^^^^^^^^^^^^
  File "/usr/local/lib/python3.11/urllib/request.py", line 251, in urlretrieve
    tfp = open(filename, 'wb')
          ^^^^^^^^^^^^^^^^^^^^
FileNotFoundError: [Errno 2] No such file or directory: '/opt/airflow/Files/Files/1918/02975099999.csv'
[2024-03-03T03:02:06.333+0000] {taskinstance.py:1149} INFO - Marking task as FAILED. dag_id=fetch_data_files, task_id=get_files, execution_date=20190318T000000, start_date=20240303T025131, end_date=20240303T030206
[2024-03-03T03:02:06.371+0000] {standard_task_runner.py:107} ERROR - Failed to execute job 4185 for task get_files ([Errno 2] No such file or directory: '/opt/airflow/Files/Files/1918/02975099999.csv'; 2910)
[2024-03-03T03:02:06.408+0000] {local_task_job_runner.py:234} INFO - Task exited with return code 1
[2024-03-03T03:02:06.429+0000] {taskinstance.py:3309} INFO - 0 downstream tasks scheduled from follow-on schedule check
