[2024-03-03T03:16:13.528+0000] {taskinstance.py:1979} INFO - Dependencies all met for dep_context=non-requeueable deps ti=<TaskInstance: fetch_data_files.get_files_6 scheduled__2016-02-23T00:00:00+00:00 [queued]>
[2024-03-03T03:16:13.545+0000] {taskinstance.py:1979} INFO - Dependencies all met for dep_context=requeueable deps ti=<TaskInstance: fetch_data_files.get_files_6 scheduled__2016-02-23T00:00:00+00:00 [queued]>
[2024-03-03T03:16:13.546+0000] {taskinstance.py:2193} INFO - Starting attempt 1 of 1
[2024-03-03T03:16:13.574+0000] {taskinstance.py:2214} INFO - Executing <Task(PythonOperator): get_files_6> on 2016-02-23 00:00:00+00:00
[2024-03-03T03:16:13.585+0000] {standard_task_runner.py:60} INFO - Started process 912 to run task
[2024-03-03T03:16:13.590+0000] {standard_task_runner.py:87} INFO - Running: ['***', 'tasks', 'run', 'fetch_data_files', 'get_files_6', 'scheduled__2016-02-23T00:00:00+00:00', '--job-id', '334', '--raw', '--subdir', 'DAGS_FOLDER/dummy_dag.py', '--cfg-path', '/tmp/tmpb6g45t3p']
[2024-03-03T03:16:13.595+0000] {standard_task_runner.py:88} INFO - Job 334: Subtask get_files_6
[2024-03-03T03:16:13.625+0000] {logging_mixin.py:188} WARNING - /home/***/.local/lib/python3.11/site-packages/***/settings.py:194 DeprecationWarning: The sql_alchemy_conn option in [core] has been moved to the sql_alchemy_conn option in [database] - the old setting has been used, but please update your config.
[2024-03-03T03:16:13.700+0000] {task_command.py:423} INFO - Running <TaskInstance: fetch_data_files.get_files_6 scheduled__2016-02-23T00:00:00+00:00 [running]> on host eb03c8b8b5fd
[2024-03-03T03:16:13.872+0000] {taskinstance.py:2510} INFO - Exporting env vars: AIRFLOW_CTX_DAG_OWNER='***' AIRFLOW_CTX_DAG_ID='fetch_data_files' AIRFLOW_CTX_TASK_ID='get_files_6' AIRFLOW_CTX_EXECUTION_DATE='2016-02-23T00:00:00+00:00' AIRFLOW_CTX_TRY_NUMBER='1' AIRFLOW_CTX_DAG_RUN_ID='scheduled__2016-02-23T00:00:00+00:00'
[2024-03-03T03:16:15.015+0000] {taskinstance.py:2728} ERROR - Task failed with exception
Traceback (most recent call last):
  File "/home/airflow/.local/lib/python3.11/site-packages/airflow/models/taskinstance.py", line 444, in _execute_task
    result = _execute_callable(context=context, **execute_callable_kwargs)
             ^^^^^^^^^^^^^^^^^^^^^^^^^^^^^^^^^^^^^^^^^^^^^^^^^^^^^^^^^^^^^
  File "/home/airflow/.local/lib/python3.11/site-packages/airflow/models/taskinstance.py", line 414, in _execute_callable
    return execute_callable(context=context, **execute_callable_kwargs)
           ^^^^^^^^^^^^^^^^^^^^^^^^^^^^^^^^^^^^^^^^^^^^^^^^^^^^^^^^^^^^
  File "/home/airflow/.local/lib/python3.11/site-packages/airflow/operators/python.py", line 200, in execute
    return_value = self.execute_callable()
                   ^^^^^^^^^^^^^^^^^^^^^^^
  File "/home/airflow/.local/lib/python3.11/site-packages/airflow/operators/python.py", line 217, in execute_callable
    return self.python_callable(*self.op_args, **self.op_kwargs)
           ^^^^^^^^^^^^^^^^^^^^^^^^^^^^^^^^^^^^^^^^^^^^^^^^^^^^^
  File "/opt/airflow/dags/dummy_dag.py", line 29, in download_years_list
    page = urlopen(url)
           ^^^^^^^^^^^^
  File "/usr/local/lib/python3.11/urllib/request.py", line 216, in urlopen
    return opener.open(url, data, timeout)
           ^^^^^^^^^^^^^^^^^^^^^^^^^^^^^^^
  File "/usr/local/lib/python3.11/urllib/request.py", line 525, in open
    response = meth(req, response)
               ^^^^^^^^^^^^^^^^^^^
  File "/usr/local/lib/python3.11/urllib/request.py", line 634, in http_response
    response = self.parent.error(
               ^^^^^^^^^^^^^^^^^^
  File "/usr/local/lib/python3.11/urllib/request.py", line 563, in error
    return self._call_chain(*args)
           ^^^^^^^^^^^^^^^^^^^^^^^
  File "/usr/local/lib/python3.11/urllib/request.py", line 496, in _call_chain
    result = func(*args)
             ^^^^^^^^^^^
  File "/usr/local/lib/python3.11/urllib/request.py", line 643, in http_error_default
    raise HTTPError(req.full_url, code, msg, hdrs, fp)
urllib.error.HTTPError: HTTP Error 404: Not Found
[2024-03-03T03:16:15.117+0000] {taskinstance.py:1149} INFO - Marking task as FAILED. dag_id=fetch_data_files, task_id=get_files_6, execution_date=20160223T000000, start_date=20240303T031613, end_date=20240303T031615
[2024-03-03T03:16:15.141+0000] {standard_task_runner.py:107} ERROR - Failed to execute job 334 for task get_files_6 (HTTP Error 404: Not Found; 912)
[2024-03-03T03:16:15.173+0000] {local_task_job_runner.py:234} INFO - Task exited with return code 1
[2024-03-03T03:16:15.244+0000] {taskinstance.py:3309} INFO - 0 downstream tasks scheduled from follow-on schedule check
[2024-03-03T03:32:10.286+0000] {taskinstance.py:1979} INFO - Dependencies all met for dep_context=non-requeueable deps ti=<TaskInstance: fetch_data_files.get_files_6 scheduled__2016-02-23T00:00:00+00:00 [queued]>
[2024-03-03T03:32:10.301+0000] {taskinstance.py:1979} INFO - Dependencies all met for dep_context=requeueable deps ti=<TaskInstance: fetch_data_files.get_files_6 scheduled__2016-02-23T00:00:00+00:00 [queued]>
[2024-03-03T03:32:10.302+0000] {taskinstance.py:2193} INFO - Starting attempt 1 of 1
[2024-03-03T03:32:10.324+0000] {taskinstance.py:2214} INFO - Executing <Task(PythonOperator): get_files_6> on 2016-02-23 00:00:00+00:00
[2024-03-03T03:32:10.332+0000] {standard_task_runner.py:60} INFO - Started process 968 to run task
[2024-03-03T03:32:10.337+0000] {standard_task_runner.py:87} INFO - Running: ['***', 'tasks', 'run', 'fetch_data_files', 'get_files_6', 'scheduled__2016-02-23T00:00:00+00:00', '--job-id', '335', '--raw', '--subdir', 'DAGS_FOLDER/dummy_dag.py', '--cfg-path', '/tmp/tmp831izown']
[2024-03-03T03:32:10.341+0000] {standard_task_runner.py:88} INFO - Job 335: Subtask get_files_6
[2024-03-03T03:32:10.367+0000] {logging_mixin.py:188} WARNING - /home/***/.local/lib/python3.11/site-packages/***/settings.py:194 DeprecationWarning: The sql_alchemy_conn option in [core] has been moved to the sql_alchemy_conn option in [database] - the old setting has been used, but please update your config.
[2024-03-03T03:32:10.421+0000] {task_command.py:423} INFO - Running <TaskInstance: fetch_data_files.get_files_6 scheduled__2016-02-23T00:00:00+00:00 [running]> on host 716a53fa82e1
[2024-03-03T03:32:10.542+0000] {taskinstance.py:2510} INFO - Exporting env vars: AIRFLOW_CTX_DAG_OWNER='***' AIRFLOW_CTX_DAG_ID='fetch_data_files' AIRFLOW_CTX_TASK_ID='get_files_6' AIRFLOW_CTX_EXECUTION_DATE='2016-02-23T00:00:00+00:00' AIRFLOW_CTX_TRY_NUMBER='1' AIRFLOW_CTX_DAG_RUN_ID='scheduled__2016-02-23T00:00:00+00:00'
[2024-03-03T03:32:11.791+0000] {taskinstance.py:2728} ERROR - Task failed with exception
Traceback (most recent call last):
  File "/home/airflow/.local/lib/python3.11/site-packages/airflow/models/taskinstance.py", line 444, in _execute_task
    result = _execute_callable(context=context, **execute_callable_kwargs)
             ^^^^^^^^^^^^^^^^^^^^^^^^^^^^^^^^^^^^^^^^^^^^^^^^^^^^^^^^^^^^^
  File "/home/airflow/.local/lib/python3.11/site-packages/airflow/models/taskinstance.py", line 414, in _execute_callable
    return execute_callable(context=context, **execute_callable_kwargs)
           ^^^^^^^^^^^^^^^^^^^^^^^^^^^^^^^^^^^^^^^^^^^^^^^^^^^^^^^^^^^^
  File "/home/airflow/.local/lib/python3.11/site-packages/airflow/operators/python.py", line 200, in execute
    return_value = self.execute_callable()
                   ^^^^^^^^^^^^^^^^^^^^^^^
  File "/home/airflow/.local/lib/python3.11/site-packages/airflow/operators/python.py", line 217, in execute_callable
    return self.python_callable(*self.op_args, **self.op_kwargs)
           ^^^^^^^^^^^^^^^^^^^^^^^^^^^^^^^^^^^^^^^^^^^^^^^^^^^^^
  File "/opt/airflow/dags/dummy_dag.py", line 30, in download_years_list
    page = urlopen(url)
           ^^^^^^^^^^^^
  File "/usr/local/lib/python3.11/urllib/request.py", line 216, in urlopen
    return opener.open(url, data, timeout)
           ^^^^^^^^^^^^^^^^^^^^^^^^^^^^^^^
  File "/usr/local/lib/python3.11/urllib/request.py", line 525, in open
    response = meth(req, response)
               ^^^^^^^^^^^^^^^^^^^
  File "/usr/local/lib/python3.11/urllib/request.py", line 634, in http_response
    response = self.parent.error(
               ^^^^^^^^^^^^^^^^^^
  File "/usr/local/lib/python3.11/urllib/request.py", line 563, in error
    return self._call_chain(*args)
           ^^^^^^^^^^^^^^^^^^^^^^^
  File "/usr/local/lib/python3.11/urllib/request.py", line 496, in _call_chain
    result = func(*args)
             ^^^^^^^^^^^
  File "/usr/local/lib/python3.11/urllib/request.py", line 643, in http_error_default
    raise HTTPError(req.full_url, code, msg, hdrs, fp)
urllib.error.HTTPError: HTTP Error 404: Not Found
[2024-03-03T03:32:11.857+0000] {taskinstance.py:1149} INFO - Marking task as FAILED. dag_id=fetch_data_files, task_id=get_files_6, execution_date=20160223T000000, start_date=20240303T033210, end_date=20240303T033211
[2024-03-03T03:32:11.874+0000] {standard_task_runner.py:107} ERROR - Failed to execute job 335 for task get_files_6 (HTTP Error 404: Not Found; 968)
[2024-03-03T03:32:11.923+0000] {local_task_job_runner.py:234} INFO - Task exited with return code 1
[2024-03-03T03:32:11.946+0000] {taskinstance.py:3309} INFO - 0 downstream tasks scheduled from follow-on schedule check
